Workbook

Sheet BASE DE DATOS
A1: dias laborales 2026 | B1: Preparacion | C1: Articulo | D1: Centro | E1: Volumen anual | F1: Piezas por minuto | G1: Piezas por hora | H1: piezas por dia(16h) | I1: piezas por dia(24h) | J1: Piezas por dia con OEE-24H | K1: Piezas por dia con OEE-16H | L1: piezas por semana (5dias)-24H | M1: piezas por semana (5dias)-16H | N1: %OEE
A2: 238 | B2: 0 | C2: 420321 | D2: 506 | E2: =VLOOKUP(C2,Hoja1!A2:B440,2,0) -> 220000 | F2: =G2/60 -> 83.333333 | G2: 5000 | H2: =G2*16 -> 80000 | I2: =G2*24 -> 120000 | J2: =I2*N2 -> 69288 | K2: =H2*N2 -> 46192 | L2: =I2*5 -> 600000 | M2: =H2*5 -> 400000 | N2: 0.5774
A3: 238 | B3: 0 | C3: 420323 | D3: 506 | E3: 80000 | F3: =G3/60 -> 50 | G3: 3000 | H3: =G3*16 -> 48000 | I3: =G3*24 -> 72000 | J3: =I3*N3 -> 43200 | K3: =H3*N3 -> 28800 | L3: =I3*5 -> 360000 | M3: =H3*5 -> 240000 | N3: 0.6
A4: 238 | B4: 0 | C4: 420324 | D4: 504 | E4: =VLOOKUP(C4,Hoja1!A4:B442,2,0) -> 362000 | F4: =G4/60 -> 48.333333 | G4: 2900 | H4: =G4*16 -> 46400 | I4: =G4*24 -> 69600 | J4: =I4*N4 -> 32426.64 | K4: =H4*N4 -> 21617.76 | L4: =I4*5 -> 348000 | M4: =H4*5 -> 232000 | N4: 0.4659
A5: 238 | B5: 0 | C5: 421016 | D5: 504 | E5: 40000 | F5: =G5/60 -> 70 | G5: 4200 | H5: =G5*16 -> 67200 | I5: =G5*24 -> 100800 | J5: =I5*N5 -> 88230.24 | K5: =H5*N5 -> 58820.16 | L5: =I5*5 -> 504000 | M5: =H5*5 -> 336000 | N5: 0.8753
A6: 238 | B6: 0 | C6: 421019 | D6: 506 | E6: =VLOOKUP(C6,Hoja1!A6:B444,2,0) -> 12000 | F6: =G6/60 -> 100 | G6: 6000 | H6: =G6*16 -> 96000 | I6: =G6*24 -> 144000 | J6: =I6*N6 -> 65462.4 | K6: =H6*N6 -> 43641.6 | L6: =I6*5 -> 720000 | M6: =H6*5 -> 480000 | N6: 0.4546
A7: 238 | B7: 0 | C7: 421109C | D7: 507 | E7: =VLOOKUP(C7,Hoja1!A7:B445,2,0) -> 3520000 | F7: =G7/60 -> 58.333333 | G7: 3500 | H7: =G7*16 -> 56000 | I7: =G7*24 -> 84000 | J7: =I7*N7 -> 63000 | K7: =H7*N7 -> 42000 | L7: =I7*5 -> 420000 | M7: =H7*5 -> 280000 | N7: 0.75
A8: 238 | B8: 0 | C8: 421175 | D8: 506 | E8: =VLOOKUP(C8,Hoja1!A8:B446,2,0) -> 0 | F8: =G8/60 -> 100 | G8: 6000 | H8: =G8*16 -> 96000 | I8: =G8*24 -> 144000 | J8: =I8*N8 -> 37828.8 | K8: =H8*N8 -> 25219.2 | L8: =I8*5 -> 720000 | M8: =H8*5 -> 480000 | N8: 0.2627
A9: 238 | B9: 0 | C9: 421404D | D9: 505 | E9: =VLOOKUP(C9,Hoja1!A9:B447,2,0) -> 180000 | F9: =G9/60 -> 50 | G9: 3000 | H9: =G9*16 -> 48000 | I9: =G9*24 -> 72000 | J9: =I9*N9 -> 46080 | K9: =H9*N9 -> 30720 | L9: =I9*5 -> 360000 | M9: =H9*5 -> 240000 | N9: 0.64
A10: 238 | B10: 0 | C10: 421429F | D10: 506 | E10: =VLOOKUP(C10,Hoja1!A10:B448,2,0) -> 1411200 | F10: =G10/60 -> 116.68333 | G10: 7001 | H10: =G10*16 -> 112016 | I10: =G10*24 -> 168024 | J10: =I10*N10 -> 117868.84 | K10: =H10*N10 -> 78579.224 | L10: =I10*5 -> 840120 | M10: =H10*5 -> 560080 | N10: 0.7015
A11: 238 | B11: 0 | C11: 421613A | D11: 505 | E11: =VLOOKUP(C11,Hoja1!A11:B449,2,0) -> 735000 | F11: =G11/60 -> 60 | G11: 3600 | H11: =G11*16 -> 57600 | I11: =G11*24 -> 86400 | J11: =I11*N11 -> 56160 | K11: =H11*N11 -> 37440 | L11: =I11*5 -> 432000 | M11: =H11*5 -> 288000 | N11: 0.65
A12: 238 | B12: 0 | C12: 421895B | D12: 502 | E12: =VLOOKUP(C12,Hoja1!A12:B450,2,0) -> 30000 | F12: =G12/60 -> 66.666667 | G12: 4000 | H12: =G12*16 -> 64000 | I12: =G12*24 -> 96000 | J12: =I12*N12 -> 39264 | K12: =H12*N12 -> 26176 | L12: =I12*5 -> 480000 | M12: =H12*5 -> 320000 | N12: 0.409
A13: 238 | B13: 0 | C13: 422060 | D13: 505 | E13: =VLOOKUP(C13,Hoja1!A13:B451,2,0) -> 0 | F13: =G13/60 -> 50 | G13: 3000 | H13: =G13*16 -> 48000 | I13: =G13*24 -> 72000 | J13: =I13*N13 -> 18993.6 | K13: =H13*N13 -> 12662.4 | L13: =I13*5 -> 360000 | M13: =H13*5 -> 240000 | N13: 0.2638
A14: 238 | B14: 0 | C14: 422086 | D14: 504 | E14: =VLOOKUP(C14,Hoja1!A14:B452,2,0) -> 1012000 | F14: =G14/60 -> 50 | G14: 3000 | H14: =G14*16 -> 48000 | I14: =G14*24 -> 72000 | J14: =I14*N14 -> 51033.6 | K14: =H14*N14 -> 34022.4 | L14: =I14*5 -> 360000 | M14: =H14*5 -> 240000 | N14: 0.7088
A15: 238 | B15: 0 | C15: 422087E | D15: 502 | E15: =VLOOKUP(C15,Hoja1!A15:B453,2,0) -> 792000 | F15: =G15/60 -> 58.333333 | G15: 3500 | H15: =G15*16 -> 56000 | I15: =G15*24 -> 84000 | J15: =I15*N15 -> 37800 | K15: =H15*N15 -> 25200 | L15: =I15*5 -> 420000 | M15: =H15*5 -> 280000 | N15: 0.45
A16: 238 | B16: 0 | C16: 422125A | D16: 504 | E16: =VLOOKUP(C16,Hoja1!A16:B454,2,0) -> 708000 | F16: =G16/60 -> 58.333333 | G16: 3500 | H16: =G16*16 -> 56000 | I16: =G16*24 -> 84000 | J16: =I16*N16 -> 50400 | K16: =H16*N16 -> 33600 | L16: =I16*5 -> 420000 | M16: =H16*5 -> 280000 | N16: 0.6
A17: 238 | B17: 0 | C17: 422125MAS | D17: 504 | E17: =VLOOKUP(C17,Hoja1!A17:B455,2,0) -> 20000 | F17: =G17/60 -> 58.333333 | G17: 3500 | H17: =G17*16 -> 56000 | I17: =G17*24 -> 84000 | J17: =I17*N17 -> 50400 | K17: =H17*N17 -> 33600 | L17: =I17*5 -> 420000 | M17: =H17*5 -> 280000 | N17: 0.6
A18: 238 | B18: 0 | C18: 422136 | D18: 505 | E18: =VLOOKUP(C18,Hoja1!A18:B456,2,0) -> 234000 | F18: =G18/60 -> 83.333333 | G18: 5000 | H18: =G18*16 -> 80000 | I18: =G18*24 -> 120000 | J18: =I18*N18 -> 72000 | K18: =H18*N18 -> 48000 | L18: =I18*5 -> 600000 | M18: =H18*5 -> 400000 | N18: 0.6
A19: 238 | B19: 0 | C19: 422151E | D19: 504 | E19: 20000 | F19: =G19/60 -> 50 | G19: 3000 | H19: =G19*16 -> 48000 | I19: =G19*24 -> 72000 | J19: =I19*N19 -> 43200 | K19: =H19*N19 -> 28800 | L19: =I19*5 -> 360000 | M19: =H19*5 -> 240000 | N19: 0.6
A20: 238 | B20: 0 | C20: 422449 | D20: 504 | E20: =VLOOKUP(C20,Hoja1!A20:B458,2,0) -> 1500000 | F20: =G20/60 -> 50 | G20: 3000 | H20: =G20*16 -> 48000 | I20: =G20*24 -> 72000 | J20: =I20*N20 -> 52891.2 | K20: =H20*N20 -> 35260.8 | L20: =I20*5 -> 360000 | M20: =H20*5 -> 240000 | N20: 0.7346
A21: 238 | B21: 0 | C21: 422661B | D21: 505 | E21: =VLOOKUP(C21,Hoja1!A21:B459,2,0) -> 0 | F21: =G21/60 -> 75 | G21: 4500 | H21: =G21*16 -> 72000 | I21: =G21*24 -> 108000 | J21: =I21*N21 -> 18662.4 | K21: =H21*N21 -> 12441.6 | L21: =I21*5 -> 540000 | M21: =H21*5 -> 360000 | N21: 0.1728
A22: 238 | B22: 0 | C22: 451383 | D22: 506 | E22: =VLOOKUP(C22,Hoja1!A22:B460,2,0) -> 254000 | F22: =G22/60 -> 80 | G22: 4800 | H22: =G22*16 -> 76800 | I22: =G22*24 -> 115200 | J22: =I22*N22 -> 78462.72 | K22: =H22*N22 -> 52308.48 | L22: =I22*5 -> 576000 | M22: =H22*5 -> 384000 | N22: 0.6811
A23: 238 | B23: 0 | C23: 451384 | D23: 504 | E23: =VLOOKUP(C23,Hoja1!A23:B461,2,0) -> 66000 | F23: =G23/60 -> 50 | G23: 3000 | H23: =G23*16 -> 48000 | I23: =G23*24 -> 72000 | J23: =I23*N23 -> 64562.4 | K23: =H23*N23 -> 43041.6 | L23: =I23*5 -> 360000 | M23: =H23*5 -> 240000 | N23: 0.8967
A24: 238 | B24: 0 | C24: 451558 | D24: 506 | E24: =VLOOKUP(C24,Hoja1!A24:B462,2,0) -> 66000 | F24: =G24/60 -> 20 | G24: 1200 | H24: =G24*16 -> 19200 | I24: =G24*24 -> 28800 | J24: =I24*N24 -> 20420.64 | K24: =H24*N24 -> 13613.76 | L24: =I24*5 -> 144000 | M24: =H24*5 -> 96000 | N24: 0.70905
A25: 238 | B25: 0 | C25: 422749D | D25: 506 | E25: =VLOOKUP(C25,Hoja1!A25:B463,2,0) -> 328000 | F25: =G25/60 -> 50 | G25: 3000 | H25: =G25*16 -> 48000 | I25: =G25*24 -> 72000 | J25: =I25*N25 -> 28800 | K25: =H25*N25 -> 19200 | L25: =I25*5 -> 360000 | M25: =H25*5 -> 240000 | N25: 0.4
A26: 238 | B26: 0 | C26: 422016 | D26: 522 | E26: =VLOOKUP(C26,Hoja1!A26:B464,2,0) -> 3780000 | F26: =G26/60 -> 50 | G26: 3000 | H26: =G26*16 -> 48000 | I26: =G26*24 -> 72000 | J26: =I26*N26 -> 32400 | K26: =H26*N26 -> 21600 | L26: =I26*5 -> 360000 | M26: =H26*5 -> 240000 | N26: 0.45
A27: 238 | B27: 0 | C27: 453195 | D27: 522 | E27: =VLOOKUP(C27,Hoja1!A27:B465,2,0) -> 344000 | F27: =G27/60 -> 16.666667 | G27: 1000 | H27: =G27*16 -> 16000 | I27: =G27*24 -> 24000 | J27: =I27*N27 -> 10800 | K27: =H27*N27 -> 7200 | L27: =I27*5 -> 120000 | M27: =H27*5 -> 80000 | N27: 0.45
A28: 238 | B28: 0 | C28: 421654 | D28: 521 | E28: =VLOOKUP(C28,Hoja1!A28:B466,2,0) -> 12064000 | F28: 130 | G28: =F28*60 -> 7800 | H28: =G28*16 -> 124800 | I28: =G28*24 -> 187200 | J28: =I28*N28 -> 131040 | K28: =H28*N28 -> 87360 | L28: =I28*5 -> 936000 | M28: =H28*5 -> 624000 | N28: 0.7
A29: 238 | B29: 0 | C29: 421809B | D29: 502 | E29: =VLOOKUP(C29,Hoja1!A29:B467,2,0) -> 7700000 | F29: 100 | G29: =F29*60 -> 6000 | H29: =G29*16 -> 96000 | I29: =G29*24 -> 144000 | J29: =I29*N29 -> 76708.8 | K29: =H29*N29 -> 51139.2 | L29: =I29*5 -> 720000 | M29: =H29*5 -> 480000 | N29: 0.5327
A30: 238 | B30: 0 | C30: 422413A | D30: 523 | E30: 1840000 | F30: 80 | G30: =F30*60 -> 4800 | H30: =G30*16 -> 76800 | I30: =G30*24 -> 115200 | J30: =I30*N30 -> 74880 | K30: =H30*N30 -> 49920 | L30: =I30*5 -> 576000 | M30: =H30*5 -> 384000 | N30: 0.65
A31: 238 | B31: 0 | C31: 421728I | D31: 521 | E31: 608000 | F31: 122 | G31: =F31*60 -> 7320 | H31: =G31*16 -> 117120 | I31: =G31*24 -> 175680 | J31: =I31*N31 -> 70272 | K31: =H31*N31 -> 46848 | L31: =I31*5 -> 878400 | M31: =H31*5 -> 585600 | N31: 0.4
A32: 238 | B32: 0 | C32: 421653L | D32: 520 | E32: =VLOOKUP(C32,Hoja1!A32:B470,2,0) -> 23312000 | F32: 140 | G32: =F32*60 -> 8400 | H32: =G32*16 -> 134400 | I32: =G32*24 -> 201600 | J32: =I32*N32 -> 151200 | K32: =H32*N32 -> 100800 | L32: =I32*5 -> 1008000 | M32: =H32*5 -> 672000 | N32: 0.75
A33: 238 | B33: 0 | C33: 421979B | D33: 550 | E33: =VLOOKUP(C33,Hoja1!A33:B471,2,0) -> 7200000 | F33: 300 | G33: =F33*60 -> 18000 | H33: =G33*16 -> 288000 | I33: =G33*24 -> 432000 | J33: =I33*N33 -> 216000 | K33: =H33*N33 -> 144000 | L33: =I33*5 -> 2160000 | M33: =H33*5 -> 1440000 | N33: 0.5
A34: 238 | B34: 0 | C34: 422185 | D34: 550 | E34: =VLOOKUP(C34,Hoja1!A34:B472,2,0) -> 290000 | F34: 50 | G34: =F34*60 -> 3000 | H34: =G34*16 -> 48000 | I34: =G34*24 -> 72000 | J34: =I34*N34 -> 33782.4 | K34: =H34*N34 -> 22521.6 | L34: =I34*5 -> 360000 | M34: =H34*5 -> 240000 | N34: 0.4692
A35: 238 | B35: 0 | C35: 422468A | D35: 550 | E35: =VLOOKUP(C35,Hoja1!A35:B473,2,0) -> 96000 | F35: 50 | G35: =F35*60 -> 3000 | H35: =G35*16 -> 48000 | I35: =G35*24 -> 72000 | J35: =I35*N35 -> 38138.4 | K35: =H35*N35 -> 25425.6 | L35: =I35*5 -> 360000 | M35: =H35*5 -> 240000 | N35: 0.5297
A36: 238 | B36: 0 | C36: 422089A | D36: 500 | E36: =VLOOKUP(C36,Hoja1!A36:B474,2,0) -> 1194000 | F36: 100 | G36: =F36*60 -> 6000 | H36: =G36*16 -> 96000 | I36: =G36*24 -> 144000 | J36: =I36*N36 -> 79200 | K36: =H36*N36 -> 52800 | L36: =I36*5 -> 720000 | M36: =H36*5 -> 480000 | N36: 0.55
A37: 238 | B37: 0 | C37: 422003 | D37: 550 | E37: =VLOOKUP(C37,Hoja1!A37:B475,2,0) -> 864000 | F37: 83 | G37: =F37*60 -> 4980 | H37: =G37*16 -> 79680 | I37: =G37*24 -> 119520 | J37: =I37*N37 -> 59760 | K37: =H37*N37 -> 39840 | L37: =I37*5 -> 597600 | M37: =H37*5 -> 398400 | N37: 0.5
A38: 238 | B38: 0 | C38: 422054B | D38: 550 | E38: =VLOOKUP(C38,Hoja1!A38:B476,2,0) -> 1908000 | F38: 83 | G38: =F38*60 -> 4980 | H38: =G38*16 -> 79680 | I38: =G38*24 -> 119520 | J38: =I38*N38 -> 59676.336 | K38: =H38*N38 -> 39784.224 | L38: =I38*5 -> 597600 | M38: =H38*5 -> 398400 | N38: 0.4993
A39: 238 | B39: 0 | C39: 422470 | D39: 550 | E39: =VLOOKUP(C39,Hoja1!A39:B477,2,0) -> 216000 | F39: 100 | G39: =F39*60 -> 6000 | H39: =G39*16 -> 96000 | I39: =G39*24 -> 144000 | J39: =I39*N39 -> 65188.8 | K39: =H39*N39 -> 43459.2 | L39: =I39*5 -> 720000 | M39: =H39*5 -> 480000 | N39: 0.4527
A40: 238 | B40: 0 | C40: 422216D | D40: 550 | E40: =VLOOKUP(C40,Hoja1!A40:B478,2,0) -> 0 | F40: 83 | G40: =F40*60 -> 4980 | H40: =G40*16 -> 79680 | I40: =G40*24 -> 119520 | J40: =I40*N40 -> 20736.72 | K40: =H40*N40 -> 13824.48 | L40: =I40*5 -> 597600 | M40: =H40*5 -> 398400 | N40: 0.1735
...

Sheet DEMANDA
P1: Articulo | Q1: Demanda Anual
P2: 400208 | Q2: 688600
P3: 400211 | Q3: 644600
P4: 400213 | Q4: 83600
P5: 400213R | Q5: 83600
P6: 400256 | Q6: 0
P7: 400279 | Q7: 0
P8: 400282 | Q8: 0
P9: 400291R | Q9: 110000
P10: 400292 | Q10: 24200
P11: 400293 | Q11: 1414600
P12: 400296 | Q12: 338800
P13: 400298 | Q13: 145200
... P441: Total general | Q441: 1.6101527e+08

Sheet Hoja1
A1: Articulo | B1: Volumen anual | C1: Articulo | D1: STOCK MEDIO OBJETIVO
A2: 400208 | B2: 688600 | C2: 421653L | D2: 1263417
A3: 400211 | B3: 644600 | C3: 421654 | D3: 742000
A4: 400213 | B4: 83600 | C4: 451860I | D4: 1118880
A5: 400213R | B5: 83600 | C5: 421979B | D5: 393000
A6: 400256 | B6: 0 | C6: 421809B | D6: 1120000
A7: 400279 | B7: 0 | C7: 421109C | D7: 366000
A8: 400282 | B8: 0 | C8: 422016 | D8: 216000
A9: 400291R | B9: 110000 | C9: 453298 | D9: 245000
A10: 400292 | B10: 24200 | C10: 422297 | D10: 460000
A11: 400293 | B11: 1414600 | C11: 421910A | D11: 121000
A12: 400296 | B12: 338800 | C12: 422054B | D12: 127000
A13: 400298 | B13: 145200 | C13: 451381A | D13: 132000
A14: 400299 | B14: 169400 | C14: 421429F | D14: 235200
A15: 400301 | B15: 13200 | C15: 422444 | D15: 98000
A16: 400303 | B16: 24200 | C16: 422443 | D16: 98000
A17: 400303B | B17: 0 | C17: 421075A | D17: 108000
A18: 400304 | B18: 13200 | C18: 453322A | D18: 111000
A19: 400307 | B19: 0 | C19: 422088 | D19: 96000
A20: 400309 | B20: 48400 | C20: 452920C | D20: 129000
A21: 400311 | B21: 1573000 | C21: 422125A | D21: 164000
A22: 400312 | B22: 59400 | C22: 422003 | D22: 104000
A23: 400312R | B23: 72600 | C23: 453074 | D23: 30600
A24: 400314 | B24: 83600 | C24: 422089A | D24: 126000
A25: 400990 | B25: 0 | C25: 422087E | D25: 198000
A26: 401451/CO | B26: 0 | C26: 422086 | D26: 128000
A27: 402035E/CO | B27: 0 | C27: 422414A | D27: 90000
A28: 402336A | B28: 9220.26 | C28: 422413A | D28: 89000
A29: 402372/CO | B29: 0 | C29: 450829 | D29: 75375
A30: 402373/CO | B30: 0 | C30: 421613A | D30: 117500
A31: 403076 | B31: 1102200 | C31: 422007 | D31: 85000
A32: 403085 | B32: 266200 | C32: 453378 | D32: 79200
A33: 403092 | B33: 0 | C33: 421867 | D33: 99000
A34: 403107 | B34: 0 | C34: 422440B | D34: 110000
A35: 403109 | B35: 132000 | C35: 453257 | D35: 26100
A36: 403110 | B36: 110000 | C36: 421728I | D36: 0
A37: 403372 | B37: 0 | C37: 421904I | D37: 0
A38: 403388 | B38: 0 | C38: 422449 | D38: 85000
A39: 403577 | B39: 0 | C39: 420321 | D39: 0
A40: 403584 | B40: 24200 | C40: 453195 | D40: 89600
...

Sheet Hoja2
A1: 400208 | B1: 142 | C1: 8000 | D1: =VLOOKUP(B1,E:F,2,0) -> 0.73372192 | E1: 102 | F1: 0.9
A2: 400208 | B2: 798 | C2: 8000 | D2: =VLOOKUP(B2,E:F,2,0) -> 0.98201054 | E2: 103 | F2: 0.9
A3: 400208 | B3: 910 | C3: 8000 | D3: =VLOOKUP(B3,E:F,2,0) -> 0.98980878 | E3: 104 | F3: 0.9
A4: 400208 | B4: 2000 | C4: 246000 | D4: =VLOOKUP(B4,E:F,2,0) -> 0.93535876 | E4: 105 | F4: 0.9
A5: 400208 | B5: 750 | C5: 5000 | D5: =VLOOKUP(B5,E:F,2,0) -> 0.82058595 | E5: 106 | F5: 0.9
A6: 400211 | B6: 142 | C6: 8000 | D6: =VLOOKUP(B6,E:F,2,0) -> 0.73372192 | E6: 107 | F6: 0.9
A7: 400211 | B7: 798 | C7: 8000 | D7: =VLOOKUP(B7,E:F,2,0) -> 0.98201054 | E7: 108 | F7: 0.9
A8: 400211 | B8: 910 | C8: 8000 | D8: =VLOOKUP(B8,E:F,2,0) -> 0.98980878 | E8: 109 | F8: 0.84156537
A9: 400211 | B9: 2000 | C9: 222000 | D9: =VLOOKUP(B9,E:F,2,0) -> 0.93535876 | E9: 122 | F9: 0.72509989
A10: 400211 | B10: 750 | C10: 5000 | D10: =VLOOKUP(B10,E:F,2,0) -> 0.82058595 | E10: 123 | F10: 0.9
A11: 400213 | B11: 142 | C11: 8000 | D11: =VLOOKUP(B11,E:F,2,0) -> 0.73372192 | E11: 124 | F11: 0.76056338
A12: 400213 | B12: 798 | C12: 8000 | D12: =VLOOKUP(B12,E:F,2,0) -> 0.98201054 | E12: 125 | F12: 0.51487675
... A15: 400213 | B15: 750 | C15: 5000 | D15: =VLOOKUP(B15,E:F,2,0) -> 0.82058595 | E15: 134 | F15: 0.9
A16: 400213R | B16: 142 | C16: 7000 | D16: =VLOOKUP(B16,E:F,2,0) -> 0.73372192 | E16: 135 | F16: 0.9
A17: 400213R | B17: 798 | C17: 7000 | D17: =VLOOKUP(B17,E:F,2,0) -> 0.98201054 | E17: 136 | F17: 0.73107264
A18: 400213R | B18: 910 | C18: 7000 | D18: =VLOOKUP(B18,E:F,2,0) -> 0.98980878 | E18: 137 | F18: 0.9
A19: 400213R | B19: 2000 | C19: 261000 | D19: =VLOOKUP(B19,E:F,2,0) -> 0.93535876 | E19: 139 | F19: 0.88259634
A20: 400213R | B20: 750 | C20: 5000 | D20: =VLOOKUP(B20,E:F,2,0) -> 0.82058595 | E20: 140 | F20: 0.9
A21: 400279 | B21: 124 | C21: 6000 | D21: =VLOOKUP(B21,E:F,2,0) -> 0.76056338 | E21: 141 | F21: 0.72618274
A22: 400279 | B22: 798 | C22: 6000 | D22: =VLOOKUP(B22,E:F,2,0) -> 0.98201054 | E22: 142 | F22: 0.73372192
A23: 400279 | B23: 910 | C23: 6000 | D23: =VLOOKUP(B23,E:F,2,0) -> 0.98980878 | E23: 205 | F23: 0.9
A24: 400279 | B24: 2700 | C24: 10000 | D24: =VLOOKUP(B24,E:F,2,0) -> 0.95856378 | E24: 206 | F24: 0.9
A25: 400279 | B25: 750 | C25: 5000 | D25: =VLOOKUP(B25,E:F,2,0) -> 0.82058595 | E25: 207 | F25: 0.90565336
A26: 400291R | B26: 142 | C26: 7000 | D26: =VLOOKUP(B26,E:F,2,0) -> 0.73372192 | E26: 210 | F26: 0.88209416
A27: 400291R | B27: 798 | C27: 7000 | D27: =VLOOKUP(B27,E:F,2,0) -> 0.98201054 | E27: 211 | F27: 0.73401501
A28: 400291R | B28: 910 | C28: 7000 | D28: =VLOOKUP(B28,E:F,2,0) -> 0.98980878 | E28: 212 | F28: 0.91115887
A29: 400291R | B29: 2000 | C29: 201000 | D29: =VLOOKUP(B29,E:F,2,0) -> 0.93535876 | E29: 213 | F29: 0.89211414
A30: 400291R | B30: 750 | C30: 5000 | D30: =VLOOKUP(B30,E:F,2,0) -> 0.82058595 | E30: 214 | F30: 0.91778021
A31: 400292 | B31: 142 | C31: 8000 | D31: =VLOOKUP(B31,E:F,2,0) -> 0.73372192 | E31: 215 | F31: 0.81343416
A32: 400292 | B32: 798 | C32: 8000 | D32: =VLOOKUP(B32,E:F,2,0) -> 0.98201054 | E32: 216 | F32: 0.89206002
A33: 400292 | B33: 910 | C33: 8000 | D33: =VLOOKUP(B33,E:F,2,0) -> 0.98980878 | E33: 217 | F33: 0.86370035
A34: 400292 | B34: 2000 | C34: 193000 | D34: =VLOOKUP(B34,E:F,2,0) -> 0.93535876 | E34: 220 | F34: 0.9
A35: 400292 | B35: 750 | C35: 5000 | D35: =VLOOKUP(B35,E:F,2,0) -> 0.82058595 | E35: 221 | F35: 0.86451774
A36: 400293 | B36: 142 | C36: 10000 | D36: =VLOOKUP(B36,E:F,2,0) -> 0.73372192 | E36: 255 | F36: 0.9
A37: 400293 | B37: 798 | C37: 10000 | D37: =VLOOKUP(B37,E:F,2,0) -> 0.98201054 | E37: 256 | F37: 0.69647683
A38: 400293 | B38: 910 | C38: 10000 | D38: =VLOOKUP(B38,E:F,2,0) -> 0.98980878 | E38: 257 | F38: 0.82485582
A39: 400293 | B39: 2000 | C39: 317000 | D39: =VLOOKUP(B39,E:F,2,0) -> 0.93535876 | E39: 258 | F39: 0.73342188
A40: 400293 | B40: 750 | C40: 6000 | D40: =VLOOKUP(B40,E:F,2,0) -> 0.82058595 | E40: 260 | F40: 0.84463021
A41: 400296 | B41: 142 | C41: 10000 | D41: =VLOOKUP(B41,E:F,2,0) -> 0.73372192 | E41: 261 | F41: 0.86363448
A42: 400296 | B42: 798 | C42: 10000 | D42: =VLOOKUP(B42,E:F,2,0) -> 0.98201054 | E42: 262 | F42: 0.84105582
...

Sheet DATOS PV 2026
A1: Articulo | B1: MEs | C1: Previsto | D1: Suma F+P | E1: PiezasDI
A2: 451106A | B2: 01-Ene | C2: 76000 | D2: 100000 | E2: 0
A3: 451106A | B3: 02-Feb | C3: 76000 | D3: 0 | E3: 0
A4: 451106A | B4: 03-Mar | C4: 76000 | D4: 100000 | E4: 0
A5: 451106A | B5: 04-Abr | C5: 76000 | D5: 100000 | E5: 0
A6: 451106A | B6: 05-May | C6: 76000 | D6: 0 | E6: 0
A7: 451106A | B7: 06-Jun | C7: 76000 | D7: 0 | E7: 0
A8: 451106A | B8: 07-Jul | C8: 76000 | D8: 0 | E8: 0
A9: 451106A | B9: 08-Ago | C9: 38000 | D9: 0 | E9: 0
A10: 451106A | B10: 09-Sep | C10: 76000 | D10: 0 | E10: 0
A11: 451106A | B11: 10-Oct | C11: 76000 | D11: 0 | E11: 0
A12: 451106A | B12: 11-Nov | C12: 76000 | D12: 0 | E12: 0
A13: 451106A | B13: 12-Dic | C13: 38000 | D13: 0 | E13: 0
... A4461: 422481 | B4461: 12-Dic | C4461: 2000 | D4461: 0 | E4461: 0
C4462: 1.6101527e+08 | D4462: 110868744 | E4462: 4011000
