Workbook

Sheet ARTÍCULOS
A1: DATOS | R1: ESTRATEGIA DE FABRICACIÓN | V1: PUNTO DE PEDIDO CUATRIMESTRAL | X1: STOCKS | AC1: LOWRUNNER | AE1: PUNTO DE PEDIDO | AF1: ='[1]DATOS PBI Artículos'!AL3 -> SEPTIEMBRE | AG1: PUNTO DE PEDIDO | AH1: ='[1]DATOS PBI Artículos'!AM3 -> OCTUBRE | AI1: PUNTO DE PEDIDO | AJ1: ='[1]DATOS PBI Artículos'!AN3 -> NOVIEMBRE | AK1: PUNTO DE PEDIDO | AL1: ='[1]DATOS PBI Artículos'!AO3 -> DICIEMBRE
A2: ARTÍCULO | B2: CV | C2: UATC | D2: Nº pedidos a futuro | E2: DEMANDA | F2: FRECUENCIA DE RECOGIDA | G2: LOTE RECOGIDA | H2: Δ LOTE RECOGIDA | I2: MCD | J2: LT + rotación | K2: Δ LT | L2: MAQ. CABECERA | M2: LOTE ECONÓMICO | N2: LOTE DE PRODUCCIÓN | O2: PROPUESTA PLANIFICACIÓN | Q2: PaP | R2: ESTRATEGIA | S2: Resultado por Lote | T2: Resultado por LT | U2: PROPUESTA PLANIFICACIÓN 2 | V2: Punto de pedido | W2: PROPUESTA PLANIFICACIÓN | X2: STOCK MÁXIMO | Y2: STOCK MEDIO | Z2: STOCK DE SEGURIDAD | AA2: Nº de huecos ocupados | AC2: Sobrecoste almacenamiento pt | AD2: SC ALM WIP | AE2: Punto de pedido | AF2: PROPUESTA PLANIFICACIÓN | AG2: Punto de pedido | AH2: PROPUESTA PLANIFICACIÓN | AI2: Punto de pedido | AJ2: PROPUESTA PLANIFICACIÓN | AK2: Punto de pedido | AL2: PROPUESTA PLANIFICACIÓN
A3: 421653L | B3: =_xlfn.XLOOKUP($A3,'[1]DATOS PBI Artículos'!A:A,'[1]DATOS PBI Artículos'!B:B) -> 0 | C3: =_xlfn.XLOOKUP($A3,'[1]DATOS PBI Artículos'!A:A,'[1]DATOS PBI Artículos'!C:C) -> UA01 | D3: =_xlfn.XLOOKUP(A3,'[1]DATOS PBI Artículos'!A:A,'[1]DATOS PBI Artículos'!T:T) -> 89 | E3: =IF(_xlfn.XLOOKUP($A3,'[1]DATOS PBI Artículos'!A:A,'[1]DATOS PBI Artículos'!AK:AK)="",_xlfn.XLOOKUP($A3,'[1]DATOS PBI Artículos'!A:A,'[1]DATOS PBI Artículos'!AJ:AJ),_xlfn.XLOOKUP($A3,'[1]DATOS PBI Artículos'!A:A,'[1]DATOS PBI Artículos'!AK:AK)) -> 9116000 | F3: =_xlfn.XLOOKUP($A3,'[1]DATOS PBI Artículos'!A:A,'[1]DATOS PBI Artículos'!AP:AP) -> 0.88 | G3: =_xlfn.XLOOKUP($A3,'[1]DATOS PBI Artículos'!A:A,'[1]DATOS PBI Artículos'!AR:AR) -> 108000 | H3: =_xlfn.XLOOKUP($A3,'[1]DATOS PBI Artículos'!A:A,'[1]DATOS PBI Artículos'!AT:AT) -> 44557.05 | I3: =_xlfn.XLOOKUP($A3,'[1]DATOS PBI Artículos'!A:A,'[1]DATOS PBI Artículos'!AS:AS) -> 4000 | J3: =IF(COUNTIF([1]CRITERIOS!$F$179:$F$199,$A3)>=1, IF(O3<>"", (O3/_xlfn.XLOOKUP(CONCATENATE(A3,L3),[1]MÁQUINAS!A:A,[1]MÁQUINAS!D:D))/24, (N3/_xlfn.XLOOKUP(CONCATENATE(A3,L3),[1]MÁQUINAS!A:A,[1]MÁQUINAS!D:D))/24), _xlfn.XLOOKUP($A3,'[1]DATOS PBI Artículos'!A:A,'[1]DATOS PBI Artículos'!AU:AU)) -> 13.162393 | K3: =_xlfn.XLOOKUP($A3,'[1]DATOS PBI Artículos'!A:A,'[1]DATOS PBI Artículos'!AV:AV) -> 1.1669093 | L3: =_xlfn.XLOOKUP(A3,[1]MÁQUINAS!B:B,[1]MÁQUINAS!C:C) -> 520 | M3: {=_xlfn.XLOOKUP(A3,'[1]DATOS PBI Artículos'!A:A,'[1]DATOS PBI Artículos'!AX:$AX)} -> 622239.07 | N3: =IF(I3="DV", E3, IF(COUNTIF([1]CRITERIOS!$I$179:$I$199,$A3)>=1, _xlfn.XLOOKUP($A3,[1]CRITERIOS!$I$179:$I$199,[1]CRITERIOS!$J$179:$J$199), IF(COUNTIF([1]CRITERIOS!$L$179:$L$199,$A3)>=1, _xlfn.CEILING.MATH(IF($M3>$E3, $E3, IF($M3<$E3/ROUNDDOWN([1]CRITERIOS!$M$16/_xlfn.XLOOKUP($C3,[1]CRITERIOS!$K$25:$K$42,[1]CRITERIOS!$M$25:$M$42), 1), E3/ROUNDDOWN([1]CRITERIOS!$M$16/_xlfn.XLOOKUP($C3,[1]CRITERIOS!$K$25:$K$42,[1]CRITERIOS!$M$25:$M$42), 1), $M3)), _xlfn.XLOOKUP($A3,[1]CRITERIOS!$L$179:$L$200,[1]CRITERIOS!$M$179:$M$200)), _xlfn.CEILING.MATH(IF($M3>$E3, $E3, IF($M3<$E3/ROUNDDOWN([1]CRITERIOS!$M$16/_xlfn.XLOOKUP($C3,[1]CRITERIOS!$K$25:$K$42,[1]CRITERIOS!$M$25:$M$42), 1), E3/ROUNDDOWN([1]CRITERIOS!$M$16/_xlfn.XLOOKUP($C3,[1]CRITERIOS!$K$25:$K$42,[1]CRITERIOS!$M$25:$M$42), 1), $M3)),_xlfn.XLOOKUP(A3,'[1]DATOS PBI Artículos'!A:A,'[1]DATOS PBI Artículos'!Z:Z ))))) -> 2464000 | Q3: =IF(AND(O3="",N3=0), 0, IF(COUNTIF([1]CRITERIOS!$F$179:$F$199,$A3)>=1, 1, IF(R3="MTO", $D3, ROUNDUP( IF(($E3-SUMIF('[1]DATOS PBI Artículos'!A:A,A3,'[1]DATOS PBI Artículos'!X:X)+($V3-_xlfn.XLOOKUP(A3,'[1]DATOS PBI Artículos'!A:A,'[1]DATOS PBI Artículos'!W:W)))<0, 0, IF(($E3-SUMIF('[1]DATOS PBI Artículos'!A:A,A3,'[1]DATOS PBI Artículos'!X:X)+$V3-_xlfn.XLOOKUP($A3,'[1]DATOS PBI Artículos'!A:A,'[1]DATOS PBI Artículos'!W:W))/IF($O3="",$N3,$O3)>ROUNDUP([1]CRITERIOS!$M$16/(IF(COUNTIF([1]CRITERIOS!$BG$11:$BG$201,L3)>=1,_xlfn.XLOOKUP($C3,[1]CRITERIOS!$K$25:$K$42,[1]CRITERIOS!$M$25:$M$42),_xlfn.XLOOKUP($C3,[1]CRITERIOS!$K$25:$K$42,[1]CRITERIOS!$M$25:$M$42))),0), ROUNDUP([1]CRITERIOS!$M$16/(IF(COUNTIF([1]CRITERIOS!$BG$11:$BG$201,$L3)>=1,_xlfn.XLOOKUP($C3,[1]CRITERIOS!$K$25:$K$42,[1]CRITERIOS!$M$25:$M$42),_xlfn.XLOOKUP($C3,[1]CRITERIOS!$K$25:$K$42,[1]CRITERIOS!$M$25:$M$42))),0), (E3+V3-SUMIF('[1]DATOS PBI Artículos'!A:A,A3,'[1]DATOS PBI Artículos'!X:X)-_xlfn.XLOOKUP(A3,'[1]DATOS PBI Artículos'!A:A,'[1]DATOS PBI Artículos'!W:W))/IF($O3="",$N3,$O3))),0)))) -> 1 | R3: =IF(U3<>"",U3,IF(F3="DV","MTO",IF(N3=0,"MTO",_xlfn.XLOOKUP(CONCATENATE(S3,T3),[1]CRITERIOS!$K$160:$K$168,[1]CRITERIOS!$N$160:$N$168)))) -> MTS | S3: =IF(G3="DV","MTO",IF(N3=0,"MTO",IF(OR(AND(N3=0,O3=""),IF(O3="",G3/N3,G3/O3)>[1]CRITERIOS!$G$163),"MTO",IF(IF(O3="",G3/N3,G3/O3)<[1]CRITERIOS!$H$161,"MTS","MTOS")))) -> MTS | T3: =IF(F3="DV","MTO",IF(OR(AND($N3=0,O3=""),$F3/$J3>[1]CRITERIOS!$G$170,$F3="DV"),"MTO",IF($F3/$J3<[1]CRITERIOS!$H$168,"MTS","MTOS"))) -> MTS | V3: =IF(R3="MTO","", IF($H3=0,(((($J3/$F3)*$G3)+$Z3)/$G3)*$G3, (($J3/$F3)*$G3)+$Z3)) -> 1770710.4 | X3: =IF(R3="MTO",0,V3+N3) -> 4234710.4 | Y3: =IF(R3="MTO",0,Z3+(N3/2)) -> 1387325.8 | Z3: =IF($R3="MTO", 0, ($H3+$K3*($E3/[1]CRITERIOS!$M$16))/[1]CRITERIOS!$X$48) -> 155325.83 | AA3: =ROUNDUP(($Y3/_xlfn.XLOOKUP($A3,'[1]DATOS PBI Artículos'!$A$4:$A$4,'[1]DATOS PBI Artículos'!$Z$4:$Z$4))/_xlfn.XLOOKUP(_xlfn.XLOOKUP($A3,'[1]DATOS PBI Artículos'!$A$4:$A$4,'[1]DATOS PBI Artículos'!$Y$4:$Y$4),[1]CRITERIOS!$P$79:$P$123,[1]CRITERIOS!$S$79:$S$123,),0) -> #DIV/0! | AB3: {=IF((E3+V3-_xlfn.XLOOKUP(A3,'[1]DATOS PBI Artículos'!$A$4:$A$4,'[1]DATOS PBI Artículos'!$W$4:$W$4))/N3>ROUNDUP([1]CRITERIOS!$M$16/(IF(COUNTIF([1]CRITERIOS!$BG$11:$BG$201,L3)>=1,_xlfn.XLOOKUP(ARTÍCULOS!L3,[1]CRITERIOS!$BG$11:$BG$201,[1]CRITERIOS!$BJ$11:$BJ$201),_xlfn.XLOOKUP(ARTÍCULOS!C3,[1]CRITERIOS!$K$25:$K$42,[1]CRITERIOS!$M$25:$M$42))),0),ROUNDUP([1]CRITERIOS!$M$16/(IF(COUNTIF([1]CRITERIOS!$BG$11:$BG$201,L3)>=1,_xlfn.XLOOKUP(ARTÍCULOS!L3,[1]CRITERIOS!$BG$11:$BG$201:#REF!,[1]CRITERIOS!$BJ$11:$BJ$201),_xlfn.XLOOKUP(ARTÍCULOS!C3,[1]CRITERIOS!$K$25:$K$42,[1]CRITERIOS!$M$25:$M$42))),0),(E3+V3-_xlfn.XLOOKUP(A3,'[1]DATOS PBI Artículos'!$A$4:$A$4,'[1]DATOS PBI Artículos'!$W$4:$W$4))/N3)} -> #DIV/0! | AC3: =IF(N3=0,"",(ROUNDUP((N3/2)/(_xlfn.XLOOKUP(A3,'[1]DATOS PBI Artículos'!$A$4:$A$4,'[1]DATOS PBI Artículos'!$Z$4:$Z$4)*_xlfn.XLOOKUP(_xlfn.XLOOKUP(A3,'[1]DATOS PBI Artículos'!$A$4:$A$4,'[1]DATOS PBI Artículos'!$Y$4:$Y$4),[1]CRITERIOS!$P$79:$P$123,[1]CRITERIOS!$S$79:$S$123)),0)*[1]CRITERIOS!$M$80*([1]CRITERIOS!$M$110/[1]CRITERIOS!$M$86)+(_xlfn.XLOOKUP(A3,'[1]DATOS PBI Artículos'!$A$4:$A$4,'[1]DATOS PBI Artículos'!$AA$4:$AA$4)*([1]CRITERIOS!$M$95+[1]CRITERIOS!$M$98)))/N3) -> #DIV/0! | AD3: =IF(N3=0,"",(ROUNDUP((N3/2)/(_xlfn.XLOOKUP(A3,'[1]DATOS PBI Artículos'!$A$4:$A$4,'[1]DATOS PBI Artículos'!$Z$4:$Z$4)*_xlfn.XLOOKUP(_xlfn.XLOOKUP(A3,'[1]DATOS PBI Artículos'!$A$4:$A$4,'[1]DATOS PBI Artículos'!$Y$4:$Y$4),[1]CRITERIOS!$P$79:$P$123,[1]CRITERIOS!$S$79:$S$123)),0)*[1]CRITERIOS!$M$80*([1]CRITERIOS!$M$89*[1]CRITERIOS!$M$92)+((_xlfn.XLOOKUP(A3,'[1]DATOS PBI Artículos'!$A$4:$A$4,'[1]DATOS PBI Artículos'!$AA$4:$AA$4)/2)*([1]CRITERIOS!$M$95+[1]CRITERIOS!$M$98)))/N3) -> #DIV/0! | AE3: =IF($R3="MTO","", IF($H3=0,ROUNDUP(((_xlfn.XLOOKUP($A3,'[1]DATOS PBI Artículos'!$A:$A,'[1]DATOS PBI Artículos'!$AL:$AL))/(_xlfn.XLOOKUP($AF$1,[1]CRITERIOS!$S$16:$S$39,[1]CRITERIOS!$Y$16:$Y$39))*$J3+$Z3)/$G3,0)*$G3, ((_xlfn.XLOOKUP($A3,'[1]DATOS PBI Artículos'!$A:$A,'[1]DATOS PBI Artículos'!$AL:$AL))/(_xlfn.XLOOKUP($AF$1,[1]CRITERIOS!$S$16:$S$39,[1]CRITERIOS!$Y$16:$Y$39))*$J3+$Z3))) -> 2005655.4 | AG3: =IF($R3="MTO","", IF($H3=0,ROUNDUP(((_xlfn.XLOOKUP($A3,'[1]DATOS PBI Artículos'!$A:$A,'[1]DATOS PBI Artículos'!$AM:$AM))/(_xlfn.XLOOKUP($AH$1,[1]CRITERIOS!$S$16:$S$39,[1]CRITERIOS!$Y$16:$Y$39))*$J3+$Z3)/$G3,0)*$G3, ((_xlfn.XLOOKUP($A3,'[1]DATOS PBI Artículos'!$A:$A,'[1]DATOS PBI Artículos'!$AM:$AM))/(_xlfn.XLOOKUP($AH$1,[1]CRITERIOS!$S$16:$S$39,[1]CRITERIOS!$Y$16:$Y$39))*$J3+$Z3))) -> 1484453.6 | AI3: =IF($R3="MTO","", IF($H3=0,ROUNDUP(((_xlfn.XLOOKUP($A3,'[1]DATOS PBI Artículos'!$A:$A,'[1]DATOS PBI Artículos'!$AN:$AN))/(_xlfn.XLOOKUP($AJ$1,[1]CRITERIOS!$S$16:$S$39,[1]CRITERIOS!$Y$16:$Y$39))*$J3+$Z3)/$G3,0)*$G3, ((_xlfn.XLOOKUP($A3,'[1]DATOS PBI Artículos'!$A:$A,'[1]DATOS PBI Artículos'!$AN:$AN))/(_xlfn.XLOOKUP($AJ$1,[1]CRITERIOS!$S$16:$S$39,[1]CRITERIOS!$Y$16:$Y$39))*$J3+$Z3))) -> 1747287.5 | AK3: =IF($R3="MTO","", IF($H3=0,ROUNDUP(((_xlfn.XLOOKUP($A3,'[1]DATOS PBI Artículos'!$A:$A,'[1]DATOS PBI Artículos'!$AO:$AO))/(_xlfn.XLOOKUP($AL$1,[1]CRITERIOS!$S$16:$S$39,[1]CRITERIOS!$Y$16:$Y$39))*$J3+$Z3)/$G3,0)*$G3, ((_xlfn.XLOOKUP($A3,'[1]DATOS PBI Artículos'!$A:$A,'[1]DATOS PBI Artículos'!$AO:$AO))/(_xlfn.XLOOKUP($AL$1,[1]CRITERIOS!$S$16:$S$39,[1]CRITERIOS!$Y$16:$Y$39))*$J3+$Z3))) -> 1889131
A4: 421654 | B4: =_xlfn.XLOOKUP($A4,'[1]DATOS PBI Artículos'!A:A,'[1]DATOS PBI Artículos'!B:B) -> 0 | C4: =_xlfn.XLOOKUP($A4,'[1]DATOS PBI Artículos'!A:A,'[1]DATOS PBI Artículos'!C:C) -> UA01 | D4: =_xlfn.XLOOKUP(A4,'[1]DATOS PBI Artículos'!A:A,'[1]DATOS PBI Artículos'!T:T) -> 68 | E4: =IF(_xlfn.XLOOKUP($A4,'[1]DATOS PBI Artículos'!A:A,'[1]DATOS PBI Artículos'!AK:AK)="",_xlfn.XLOOKUP($A4,'[1]DATOS PBI Artículos'!A:A,'[1]DATOS PBI Artículos'!AJ:AJ),_xlfn.XLOOKUP($A4,'[1]DATOS PBI Artículos'!A:A,'[1]DATOS PBI Artículos'!AK:AK)) -> 5176000 | F4: =_xlfn.XLOOKUP($A4,'[1]DATOS PBI Artículos'!A:A,'[1]DATOS PBI Artículos'!AP:AP) -> 1.1384615 | G4: =_xlfn.XLOOKUP($A4,'[1]DATOS PBI Artículos'!A:A,'[1]DATOS PBI Artículos'!AR:AR) -> 80000 | H4: =_xlfn.XLOOKUP($A4,'[1]DATOS PBI Artículos'!A:A,'[1]DATOS PBI Artículos'!AT:AT) -> 65196.05 | I4: =_xlfn.XLOOKUP($A4,'[1]DATOS PBI Artículos'!A:A,'[1]DATOS PBI Artículos'!AS:AS) -> 4000 | J4: =IF(COUNTIF([1]CRITERIOS!$F$179:$F$199,$A4)>=1, IF(O4<>"", (O4/_xlfn.XLOOKUP(CONCATENATE(A4,L4),[1]MÁQUINAS!A:A,[1]MÁQUINAS!D:D))/24, (N4/_xlfn.XLOOKUP(CONCATENATE(A4,L4),[1]MÁQUINAS!A:A,[1]MÁQUINAS!D:D))/24), _xlfn.XLOOKUP($A4,'[1]DATOS PBI Artículos'!A:A,'[1]DATOS PBI Artículos'!AU:AU)) -> 13.694444 | K4: =_xlfn.XLOOKUP($A4,'[1]DATOS PBI Artículos'!A:A,'[1]DATOS PBI Artículos'!AV:AV) -> 1.7086267 | L4: =_xlfn.XLOOKUP(A4,[1]MÁQUINAS!B:B,[1]MÁQUINAS!C:C) -> 521 | M4: {=_xlfn.XLOOKUP(A4,'[1]DATOS PBI Artículos'!A:A,'[1]DATOS PBI Artículos'!AX:$AX)} -> 647661.33 | N4: =IF(I4="DV", E4, IF(COUNTIF([1]CRITERIOS!$I$179:$I$199,$A4)>=1, _xlfn.XLOOKUP($A4,[1]CRITERIOS!$I$179:$I$199,[1]CRITERIOS!$J$179:$J$199), IF(COUNTIF([1]CRITERIOS!$L$179:$L$199,$A4)>=1, _xlfn.CEILING.MATH(IF($M4>$E4, $E4, IF($M4<$E4/ROUNDDOWN([1]CRITERIOS!$M$16/_xlfn.XLOOKUP($C4,[1]CRITERIOS!$K$25:$K$42,[1]CRITERIOS!$M$25:$M$42), 1), E4/ROUNDDOWN([1]CRITERIOS!$M$16/_xlfn.XLOOKUP($C4,[1]CRITERIOS!$K$25:$K$42,[1]CRITERIOS!$M$25:$M$42), 1), $M4)), _xlfn.XLOOKUP($A4,[1]CRITERIOS!$L$179:$L$200,[1]CRITERIOS!$M$179:$M$200)), _xlfn.CEILING.MATH(IF($M4>$E4, $E4, IF($M4<$E4/ROUNDDOWN([1]CRITERIOS!$M$16/_xlfn.XLOOKUP($C4,[1]CRITERIOS!$K$25:$K$42,[1]CRITERIOS!$M$25:$M$42), 1), E4/ROUNDDOWN([1]CRITERIOS!$M$16/_xlfn.XLOOKUP($C4,[1]CRITERIOS!$K$25:$K$42,[1]CRITERIOS!$M$25:$M$42), 1), $M4)),_xlfn.XLOOKUP(A4,'[1]DATOS PBI Artículos'!A:A,'[1]DATOS PBI Artículos'!Z:Z ))))) -> 1400000 | Q4: =IF(AND(O4="",N4=0), 0, IF(COUNTIF([1]CRITERIOS!$F$179:$F$199,$A4)>=1, 1, IF(R4="MTO", $D4, ROUNDUP( IF(($E4-SUMIF('[1]DATOS PBI Artículos'!A:A,A4,'[1]DATOS PBI Artículos'!X:X)+($V4-_xlfn.XLOOKUP(A4,'[1]DATOS PBI Artículos'!A:A,'[1]DATOS PBI Artículos'!W:W)))<0, 0, IF(($E4-SUMIF('[1]DATOS PBI Artículos'!A:A,A4,'[1]DATOS PBI Artículos'!X:X)+$V4-_xlfn.XLOOKUP($A4,'[1]DATOS PBI Artículos'!A:A,'[1]DATOS PBI Artículos'!W:W))/IF($O4="",$N4,$O4)>ROUNDUP([1]CRITERIOS!$M$16/(IF(COUNTIF([1]CRITERIOS!$BG$11:$BG$201,L4)>=1,_xlfn.XLOOKUP($C4,[1]CRITERIOS!$K$25:$K$42,[1]CRITERIOS!$M$25:$M$42),_xlfn.XLOOKUP($C4,[1]CRITERIOS!$K$25:$K$42,[1]CRITERIOS!$M$25:$M$42))),0), ROUNDUP([1]CRITERIOS!$M$16/(IF(COUNTIF([1]CRITERIOS!$BG$11:$BG$201,$L4)>=1,_xlfn.XLOOKUP($C4,[1]CRITERIOS!$K$25:$K$42,[1]CRITERIOS!$M$25:$M$42),_xlfn.XLOOKUP($C4,[1]CRITERIOS!$K$25:$K$42,[1]CRITERIOS!$M$25:$M$42))),0), (E4+V4-SUMIF('[1]DATOS PBI Artículos'!A:A,A4,'[1]DATOS PBI Artículos'!X:X)-_xlfn.XLOOKUP(A4,'[1]DATOS PBI Artículos'!A:A,'[1]DATOS PBI Artículos'!W:W))/IF($O4="",$N4,$O4))),0)))) -> 4 | R4: =IF(U4<>"",U4,IF(F4="DV","MTO",IF(N4=0,"MTO",_xlfn.XLOOKUP(CONCATENATE(S4,T4),[1]CRITERIOS!$K$160:$K$168,[1]CRITERIOS!$N$160:$N$168)))) -> MTS | S4: =IF(G4="DV","MTO",IF(N4=0,"MTO",IF(OR(AND(N4=0,O4=""),IF(O4="",G4/N4,G4/O4)>[1]CRITERIOS!$G$163),"MTO",IF(IF(O4="",G4/N4,G4/O4)<[1]CRITERIOS!$H$161,"MTS","MTOS")))) -> MTS | T4: =IF(F4="DV","MTO",IF(OR(AND($N4=0,O4=""),$F4/$J4>[1]CRITERIOS!$G$170,$F4="DV"),"MTO",IF($F4/$J4<[1]CRITERIOS!$H$168,"MTS","MTOS"))) -> MTS | V4: =IF(R4="MTO","", IF($H4=0,(((($J4/$F4)*$G4)+$Z4)/$G4)*$G4, (($J4/$F4)*$G4)+$Z4)) -> 1114907.4 | X4: =IF(R4="MTO",0,V4+N4) -> 2514907.4 | Y4: =IF(R4="MTO",0,Z4+(N4/2)) -> 852595.06 | Z4: =IF($R4="MTO", 0, ($H4+$K4*($E4/[1]CRITERIOS!$M$16))/[1]CRITERIOS!$X$48) -> 152595.06 | AA4: =ROUNDUP(($Y4/_xlfn.XLOOKUP($A4,'[1]DATOS PBI Artículos'!$A$4:$A$4,'[1]DATOS PBI Artículos'!$Z$4:$Z$4))/_xlfn.XLOOKUP(_xlfn.XLOOKUP($A4,'[1]DATOS PBI Artículos'!$A$4:$A$4,'[1]DATOS PBI Artículos'!$Y$4:$Y$4),[1]CRITERIOS!$P$79:$P$123,[1]CRITERIOS!$S$79:$S$123,),0) -> #N/A | AB4: {=IF((E4+V4-_xlfn.XLOOKUP(A4,'[1]DATOS PBI Artículos'!$A$4:$A$4,'[1]DATOS PBI Artículos'!$W$4:$W$4))/N4>ROUNDUP([1]CRITERIOS!$M$16/(IF(COUNTIF([1]CRITERIOS!$BG$11:$BG$201,L4)>=1,_xlfn.XLOOKUP(ARTÍCULOS!L4,[1]CRITERIOS!$BG$11:$BG$201,[1]CRITERIOS!$BJ$11:$BJ$201),_xlfn.XLOOKUP(ARTÍCULOS!C4,[1]CRITERIOS!$K$25:$K$42,[1]CRITERIOS!$M$25:$M$42))),0),ROUNDUP([1]CRITERIOS!$M$16/(IF(COUNTIF([1]CRITERIOS!$BG$11:$BG$201,L4)>=1,_xlfn.XLOOKUP(ARTÍCULOS!L4,[1]CRITERIOS!$BG$11:$BG$201:#REF!,[1]CRITERIOS!$BJ$11:$BJ$201),_xlfn.XLOOKUP(ARTÍCULOS!C4,[1]CRITERIOS!$K$25:$K$42,[1]CRITERIOS!$M$25:$M$42))),0),(E4+V4-_xlfn.XLOOKUP(A4,'[1]DATOS PBI Artículos'!$A$4:$A$4,'[1]DATOS PBI Artículos'!$W$4:$W$4))/N4)} -> #N/A | AC4: =IF(N4=0,"",(ROUNDUP((N4/2)/(_xlfn.XLOOKUP(A4,'[1]DATOS PBI Artículos'!$A$4:$A$4,'[1]DATOS PBI Artículos'!$Z$4:$Z$4)*_xlfn.XLOOKUP(_xlfn.XLOOKUP(A4,'[1]DATOS PBI Artículos'!$A$4:$A$4,'[1]DATOS PBI Artículos'!$Y$4:$Y$4),[1]CRITERIOS!$P$79:$P$123,[1]CRITERIOS!$S$79:$S$123)),0)*[1]CRITERIOS!$M$80*([1]CRITERIOS!$M$110/[1]CRITERIOS!$M$86)+(_xlfn.XLOOKUP(A4,'[1]DATOS PBI Artículos'!$A$4:$A$4,'[1]DATOS PBI Artículos'!$AA$4:$AA$4)*([1]CRITERIOS!$M$95+[1]CRITERIOS!$M$98)))/N4) -> #N/A | AD4: =IF(N4=0,"",(ROUNDUP((N4/2)/(_xlfn.XLOOKUP(A4,'[1]DATOS PBI Artículos'!$A$4:$A$4,'[1]DATOS PBI Artículos'!$Z$4:$Z$4)*_xlfn.XLOOKUP(_xlfn.XLOOKUP(A4,'[1]DATOS PBI Artículos'!$A$4:$A$4,'[1]DATOS PBI Artículos'!$Y$4:$Y$4),[1]CRITERIOS!$P$79:$P$123,[1]CRITERIOS!$S$79:$S$123)),0)*[1]CRITERIOS!$M$80*([1]CRITERIOS!$M$89*[1]CRITERIOS!$M$92)+((_xlfn.XLOOKUP(A4,'[1]DATOS PBI Artículos'!$A$4:$A$4,'[1]DATOS PBI Artículos'!$AA$4:$AA$4)/2)*([1]CRITERIOS!$M$95+[1]CRITERIOS!$M$98)))/N4) -> #N/A | AE4: =IF($R4="MTO","", IF($H4=0,ROUNDUP(((_xlfn.XLOOKUP($A4,'[1]DATOS PBI Artículos'!$A:$A,'[1]DATOS PBI Artículos'!$AL:$AL))/(_xlfn.XLOOKUP($AF$1,[1]CRITERIOS!$S$16:$S$39,[1]CRITERIOS!$Y$16:$Y$39))*$J4+$Z4)/$G4,0)*$G4, ((_xlfn.XLOOKUP($A4,'[1]DATOS PBI Artículos'!$A:$A,'[1]DATOS PBI Artículos'!$AL:$AL))/(_xlfn.XLOOKUP($AF$1,[1]CRITERIOS!$S$16:$S$39,[1]CRITERIOS!$Y$16:$Y$39))*$J4+$Z4))) -> 1245666.6 | AG4: =IF($R4="MTO","", IF($H4=0,ROUNDUP(((_xlfn.XLOOKUP($A4,'[1]DATOS PBI Artículos'!$A:$A,'[1]DATOS PBI Artículos'!$AM:$AM))/(_xlfn.XLOOKUP($AH$1,[1]CRITERIOS!$S$16:$S$39,[1]CRITERIOS!$Y$16:$Y$39))*$J4+$Z4)/$G4,0)*$G4, ((_xlfn.XLOOKUP($A4,'[1]DATOS PBI Artículos'!$A:$A,'[1]DATOS PBI Artículos'!$AM:$AM))/(_xlfn.XLOOKUP($AH$1,[1]CRITERIOS!$S$16:$S$39,[1]CRITERIOS!$Y$16:$Y$39))*$J4+$Z4))) -> 937769.66 | AI4: =IF($R4="MTO","", IF($H4=0,ROUNDUP(((_xlfn.XLOOKUP($A4,'[1]DATOS PBI Artículos'!$A:$A,'[1]DATOS PBI Artículos'!$AN:$AN))/(_xlfn.XLOOKUP($AJ$1,[1]CRITERIOS!$S$16:$S$39,[1]CRITERIOS!$Y$16:$Y$39))*$J4+$Z4)/$G4,0)*$G4, ((_xlfn.XLOOKUP($A4,'[1]DATOS PBI Artículos'!$A:$A,'[1]DATOS PBI Artículos'!$AN:$AN))/(_xlfn.XLOOKUP($AJ$1,[1]CRITERIOS!$S$16:$S$39,[1]CRITERIOS!$Y$16:$Y$39))*$J4+$Z4))) -> 1093037.3 | AK4: =IF($R4="MTO","", IF($H4=0,ROUNDUP(((_xlfn.XLOOKUP($A4,'[1]DATOS PBI Artículos'!$A:$A,'[1]DATOS PBI Artículos'!$AO:$AO))/(_xlfn.XLOOKUP($AL$1,[1]CRITERIOS!$S$16:$S$39,[1]CRITERIOS!$Y$16:$Y$39))*$J4+$Z4)/$G4,0)*$G4, ((_xlfn.XLOOKUP($A4,'[1]DATOS PBI Artículos'!$A:$A,'[1]DATOS PBI Artículos'!$AO:$AO))/(_xlfn.XLOOKUP($AL$1,[1]CRITERIOS!$S$16:$S$39,[1]CRITERIOS!$Y$16:$Y$39))*$J4+$Z4))) -> 1176830.5
A5: 421979B | B5: =_xlfn.XLOOKUP($A5,'[1]DATOS PBI Artículos'!A:A,'[1]DATOS PBI Artículos'!B:B) -> 0 | C5: =_xlfn.XLOOKUP($A5,'[1]DATOS PBI Artículos'!A:A,'[1]DATOS PBI Artículos'!C:C) -> UA01 | D5: =_xlfn.XLOOKUP(A5,'[1]DATOS PBI Artículos'!A:A,'[1]DATOS PBI Artículos'!T:T) -> 24 | E5: =IF(_xlfn.XLOOKUP($A5,'[1]DATOS PBI Artículos'!A:A,'[1]DATOS PBI Artículos'!AK:AK)="",_xlfn.XLOOKUP($A5,'[1]DATOS PBI Artículos'!A:A,'[1]DATOS PBI Artículos'!AJ:AJ),_xlfn.XLOOKUP($A5,'[1]DATOS PBI Artículos'!A:A,'[1]DATOS PBI Artículos'!AK:AK)) -> 2832000 | F5: =_xlfn.XLOOKUP($A5,'[1]DATOS PBI Artículos'!A:A,'[1]DATOS PBI Artículos'!AP:AP) -> 3.1428571 | G5: =_xlfn.XLOOKUP($A5,'[1]DATOS PBI Artículos'!A:A,'[1]DATOS PBI Artículos'!AR:AR) -> 120000 | H5: =_xlfn.XLOOKUP($A5,'[1]DATOS PBI Artículos'!A:A,'[1]DATOS PBI Artículos'!AT:AT) -> 37434.618 | I5: =_xlfn.XLOOKUP($A5,'[1]DATOS PBI Artículos'!A:A,'[1]DATOS PBI Artículos'!AS:AS) -> 24000 | J5: =IF(COUNTIF([1]CRITERIOS!$F$179:$F$199,$A5)>=1, IF(O5<>"", (O5/_xlfn.XLOOKUP(CONCATENATE(A5,L5),[1]MÁQUINAS!A:A,[1]MÁQUINAS!D:D))/24, (N5/_xlfn.XLOOKUP(CONCATENATE(A5,L5),[1]MÁQUINAS!A:A,[1]MÁQUINAS!D:D))/24), _xlfn.XLOOKUP($A5,'[1]DATOS PBI Artículos'!A:A,'[1]DATOS PBI Artículos'!AU:AU)) -> 22.538462 | K5: =_xlfn.XLOOKUP($A5,'[1]DATOS PBI Artículos'!A:A,'[1]DATOS PBI Artículos'!AV:AV) -> 7.1000181 | L5: =_xlfn.XLOOKUP(A5,[1]MÁQUINAS!B:B,[1]MÁQUINAS!C:C) -> 550 | M5: {=_xlfn.XLOOKUP(A5,'[1]DATOS PBI Artículos'!A:A,'[1]DATOS PBI Artículos'!AX:$AX)} -> 316711.21 | N5: =IF(I5="DV", E5, IF(COUNTIF([1]CRITERIOS!$I$179:$I$199,$A5)>=1, _xlfn.XLOOKUP($A5,[1]CRITERIOS!$I$179:$I$199,[1]CRITERIOS!$J$179:$J$199), IF(COUNTIF([1]CRITERIOS!$L$179:$L$199,$A5)>=1, _xlfn.CEILING.MATH(IF($M5>$E5, $E5, IF($M5<$E5/ROUNDDOWN([1]CRITERIOS!$M$16/_xlfn.XLOOKUP($C5,[1]CRITERIOS!$K$25:$K$42,[1]CRITERIOS!$M$25:$M$42), 1), E5/ROUNDDOWN([1]CRITERIOS!$M$16/_xlfn.XLOOKUP($C5,[1]CRITERIOS!$K$25:$K$42,[1]CRITERIOS!$M$25:$M$42), 1), $M5)), _xlfn.XLOOKUP($A5,[1]CRITERIOS!$L$179:$L$200,[1]CRITERIOS!$M$179:$M$200)), _xlfn.CEILING.MATH(IF($M5>$E5, $E5, IF($M5<$E5/ROUNDDOWN([1]CRITERIOS!$M$16/_xlfn.XLOOKUP($C5,[1]CRITERIOS!$K$25:$K$42,[1]CRITERIOS!$M$25:$M$42), 1), E5/ROUNDDOWN([1]CRITERIOS!$M$16/_xlfn.XLOOKUP($C5,[1]CRITERIOS!$K$25:$K$42,[1]CRITERIOS!$M$25:$M$42), 1), $M5)),_xlfn.XLOOKUP(A5,'[1]DATOS PBI Artículos'!A:A,'[1]DATOS PBI Artículos'!Z:Z ))))) -> 768000 | Q5: =IF(AND(O5="",N5=0), 0, IF(COUNTIF([1]CRITERIOS!$F$179:$F$199,$A5)>=1, 1, IF(R5="MTO", $D5, ROUNDUP( IF(($E5-SUMIF('[1]DATOS PBI Artículos'!A:A,A5,'[1]DATOS PBI Artículos'!X:X)+($V5-_xlfn.XLOOKUP(A5,'[1]DATOS PBI Artículos'!A:A,'[1]DATOS PBI Artículos'!W:W)))<0, 0, IF(($E5-SUMIF('[1]DATOS PBI Artículos'!A:A,A5,'[1]DATOS PBI Artículos'!X:X)+$V5-_xlfn.XLOOKUP($A5,'[1]DATOS PBI Artículos'!A:A,'[1]DATOS PBI Artículos'!W:W))/IF($O5="",$N5,$O5)>ROUNDUP([1]CRITERIOS!$M$16/(IF(COUNTIF([1]CRITERIOS!$BG$11:$BG$201,L5)>=1,_xlfn.XLOOKUP($C5,[1]CRITERIOS!$K$25:$K$42,[1]CRITERIOS!$M$25:$M$42),_xlfn.XLOOKUP($C5,[1]CRITERIOS!$K$25:$K$42,[1]CRITERIOS!$M$25:$M$42))),0), ROUNDUP([1]CRITERIOS!$M$16/(IF(COUNTIF([1]CRITERIOS!$BG$11:$BG$201,$L5)>=1,_xlfn.XLOOKUP($C5,[1]CRITERIOS!$K$25:$K$42,[1]CRITERIOS!$M$25:$M$42),_xlfn.XLOOKUP($C5,[1]CRITERIOS!$K$25:$K$42,[1]CRITERIOS!$M$25:$M$42))),0), (E5+V5-SUMIF('[1]DATOS PBI Artículos'!A:A,A5,'[1]DATOS PBI Artículos'!X:X)-_xlfn.XLOOKUP(A5,'[1]DATOS PBI Artículos'!A:A,'[1]DATOS PBI Artículos'!W:W))/IF($O5="",$N5,$O5))),0)))) -> 4 | R5: =IF(U5<>"",U5,IF(F5="DV","MTO",IF(N5=0,"MTO",_xlfn.XLOOKUP(CONCATENATE(S5,T5),[1]CRITERIOS!$K$160:$K$168,[1]CRITERIOS!$N$160:$N$168)))) -> MTS | S5: =IF(G5="DV","MTO",IF(N5=0,"MTO",IF(OR(AND(N5=0,O5=""),IF(O5="",G5/N5,G5/O5)>[1]CRITERIOS!$G$163),"MTO",IF(IF(O5="",G5/N5,G5/O5)<[1]CRITERIOS!$H$161,"MTS","MTOS")))) -> MTS | T5: =IF(F5="DV","MTO",IF(OR(AND($N5=0,O5=""),$F5/$J5>[1]CRITERIOS!$G$170,$F5="DV"),"MTO",IF($F5/$J5<[1]CRITERIOS!$H$168,"MTS","MTOS"))) -> MTS | V5: =IF(R5="MTO","", IF($H5=0,(((($J5/$F5)*$G5)+$Z5)/$G5)*$G5, (($J5/$F5)*$G5)+$Z5)) -> 1115168.9 | X5: =IF(R5="MTO",0,V5+N5) -> 1883168.9 | Y5: =IF(R5="MTO",0,Z5+(N5/2)) -> 638609.42 | Z5: =IF($R5="MTO", 0, ($H5+$K5*($E5/[1]CRITERIOS!$M$16))/[1]CRITERIOS!$X$48) -> 254609.42 | AA5: =ROUNDUP(($Y5/_xlfn.XLOOKUP($A5,'[1]DATOS PBI Artículos'!$A$4:$A$4,'[1]DATOS PBI Artículos'!$Z$4:$Z$4))/_xlfn.XLOOKUP(_xlfn.XLOOKUP($A5,'[1]DATOS PBI Artículos'!$A$4:$A$4,'[1]DATOS PBI Artículos'!$Y$4:$Y$4),[1]CRITERIOS!$P$79:$P$123,[1]CRITERIOS!$S$79:$S$123,),0) -> #N/A | AB5: {=IF((E5+V5-_xlfn.XLOOKUP(A5,'[1]DATOS PBI Artículos'!$A$4:$A$4,'[1]DATOS PBI Artículos'!$W$4:$W$4))/N5>ROUNDUP([1]CRITERIOS!$M$16/(IF(COUNTIF([1]CRITERIOS!$BG$11:$BG$201,L5)>=1,_xlfn.XLOOKUP(ARTÍCULOS!L5,[1]CRITERIOS!$BG$11:$BG$201,[1]CRITERIOS!$BJ$11:$BJ$201),_xlfn.XLOOKUP(ARTÍCULOS!C5,[1]CRITERIOS!$K$25:$K$42,[1]CRITERIOS!$M$25:$M$42))),0),ROUNDUP([1]CRITERIOS!$M$16/(IF(COUNTIF([1]CRITERIOS!$BG$11:$BG$201,L5)>=1,_xlfn.XLOOKUP(ARTÍCULOS!L5,[1]CRITERIOS!$BG$11:$BG$201:#REF!,[1]CRITERIOS!$BJ$11:$BJ$201),_xlfn.XLOOKUP(ARTÍCULOS!C5,[1]CRITERIOS!$K$25:$K$42,[1]CRITERIOS!$M$25:$M$42))),0),(E5+V5-_xlfn.XLOOKUP(A5,'[1]DATOS PBI Artículos'!$A$4:$A$4,'[1]DATOS PBI Artículos'!$W$4:$W$4))/N5)} -> #N/A | AC5: =IF(N5=0,"",(ROUNDUP((N5/2)/(_xlfn.XLOOKUP(A5,'[1]DATOS PBI Artículos'!$A$4:$A$4,'[1]DATOS PBI Artículos'!$Z$4:$Z$4)*_xlfn.XLOOKUP(_xlfn.XLOOKUP(A5,'[1]DATOS PBI Artículos'!$A$4:$A$4,'[1]DATOS PBI Artículos'!$Y$4:$Y$4),[1]CRITERIOS!$P$79:$P$123,[1]CRITERIOS!$S$79:$S$123)),0)*[1]CRITERIOS!$M$80*([1]CRITERIOS!$M$110/[1]CRITERIOS!$M$86)+(_xlfn.XLOOKUP(A5,'[1]DATOS PBI Artículos'!$A$4:$A$4,'[1]DATOS PBI Artículos'!$AA$4:$AA$4)*([1]CRITERIOS!$M$95+[1]CRITERIOS!$M$98)))/N5) -> #N/A | AD5: =IF(N5=0,"",(ROUNDUP((N5/2)/(_xlfn.XLOOKUP(A5,'[1]DATOS PBI Artículos'!$A$4:$A$4,'[1]DATOS PBI Artículos'!$Z$4:$Z$4)*_xlfn.XLOOKUP(_xlfn.XLOOKUP(A5,'[1]DATOS PBI Artículos'!$A$4:$A$4,'[1]DATOS PBI Artículos'!$Y$4:$Y$4),[1]CRITERIOS!$P$79:$P$123,[1]CRITERIOS!$S$79:$S$123)),0)*[1]CRITERIOS!$M$80*([1]CRITERIOS!$M$89*[1]CRITERIOS!$M$92)+((_xlfn.XLOOKUP(A5,'[1]DATOS PBI Artículos'!$A$4:$A$4,'[1]DATOS PBI Artículos'!$AA$4:$AA$4)/2)*([1]CRITERIOS!$M$95+[1]CRITERIOS!$M$98)))/N5) -> #N/A | AE5: =IF($R5="MTO","", IF($H5=0,ROUNDUP(((_xlfn.XLOOKUP($A5,'[1]DATOS PBI Artículos'!$A:$A,'[1]DATOS PBI Artículos'!$AL:$AL))/(_xlfn.XLOOKUP($AF$1,[1]CRITERIOS!$S$16:$S$39,[1]CRITERIOS!$Y$16:$Y$39))*$J5+$Z5)/$G5,0)*$G5, ((_xlfn.XLOOKUP($A5,'[1]DATOS PBI Artículos'!$A:$A,'[1]DATOS PBI Artículos'!$AL:$AL))/(_xlfn.XLOOKUP($AF$1,[1]CRITERIOS!$S$16:$S$39,[1]CRITERIOS!$Y$16:$Y$39))*$J5+$Z5))) -> 1238909.3 | AG5: =IF($R5="MTO","", IF($H5=0,ROUNDUP(((_xlfn.XLOOKUP($A5,'[1]DATOS PBI Artículos'!$A:$A,'[1]DATOS PBI Artículos'!$AM:$AM))/(_xlfn.XLOOKUP($AH$1,[1]CRITERIOS!$S$16:$S$39,[1]CRITERIOS!$Y$16:$Y$39))*$J5+$Z5)/$G5,0)*$G5, ((_xlfn.XLOOKUP($A5,'[1]DATOS PBI Artículos'!$A:$A,'[1]DATOS PBI Artículos'!$AM:$AM))/(_xlfn.XLOOKUP($AH$1,[1]CRITERIOS!$S$16:$S$39,[1]CRITERIOS!$Y$16:$Y$39))*$J5+$Z5))) -> 961651.19 | AI5: =IF($R5="MTO","", IF($H5=0,ROUNDUP(((_xlfn.XLOOKUP($A5,'[1]DATOS PBI Artículos'!$A:$A,'[1]DATOS PBI Artículos'!$AN:$AN))/(_xlfn.XLOOKUP($AJ$1,[1]CRITERIOS!$S$16:$S$39,[1]CRITERIOS!$Y$16:$Y$39))*$J5+$Z5)/$G5,0)*$G5, ((_xlfn.XLOOKUP($A5,'[1]DATOS PBI Artículos'!$A:$A,'[1]DATOS PBI Artículos'!$AN:$AN))/(_xlfn.XLOOKUP($AJ$1,[1]CRITERIOS!$S$16:$S$39,[1]CRITERIOS!$Y$16:$Y$39))*$J5+$Z5))) -> 1101468.1 | AK5: =IF($R5="MTO","", IF($H5=0,ROUNDUP(((_xlfn.XLOOKUP($A5,'[1]DATOS PBI Artículos'!$A:$A,'[1]DATOS PBI Artículos'!$AO:$AO))/(_xlfn.XLOOKUP($AL$1,[1]CRITERIOS!$S$16:$S$39,[1]CRITERIOS!$Y$16:$Y$39))*$J5+$Z5)/$G5,0)*$G5, ((_xlfn.XLOOKUP($A5,'[1]DATOS PBI Artículos'!$A:$A,'[1]DATOS PBI Artículos'!$AO:$AO))/(_xlfn.XLOOKUP($AL$1,[1]CRITERIOS!$S$16:$S$39,[1]CRITERIOS!$Y$16:$Y$39))*$J5+$Z5))) -> 1176923
A6: 451860I | B6: =_xlfn.XLOOKUP($A6,'[1]DATOS PBI Artículos'!A:A,'[1]DATOS PBI Artículos'!B:B) -> 0 | C6: =_xlfn.XLOOKUP($A6,'[1]DATOS PBI Artículos'!A:A,'[1]DATOS PBI Artículos'!C:C) -> UA01 | D6: =_xlfn.XLOOKUP(A6,'[1]DATOS PBI Artículos'!A:A,'[1]DATOS PBI Artículos'!T:T) -> 8 | E6: =IF(_xlfn.XLOOKUP($A6,'[1]DATOS PBI Artículos'!A:A,'[1]DATOS PBI Artículos'!AK:AK)="",_xlfn.XLOOKUP($A6,'[1]DATOS PBI Artículos'!A:A,'[1]DATOS PBI Artículos'!AJ:AJ),_xlfn.XLOOKUP($A6,'[1]DATOS PBI Artículos'!A:A,'[1]DATOS PBI Artículos'!AK:AK)) -> 2681280 | F6: =_xlfn.XLOOKUP($A6,'[1]DATOS PBI Artículos'!A:A,'[1]DATOS PBI Artículos'!AP:AP) -> 9 | G6: =_xlfn.XLOOKUP($A6,'[1]DATOS PBI Artículos'!A:A,'[1]DATOS PBI Artículos'!AR:AR) -> 342720 | H6: =_xlfn.XLOOKUP($A6,'[1]DATOS PBI Artículos'!A:A,'[1]DATOS PBI Artículos'!AT:AT) -> 415809.82 | I6: =_xlfn.XLOOKUP($A6,'[1]DATOS PBI Artículos'!A:A,'[1]DATOS PBI Artículos'!AS:AS) -> 20160 | J6: =IF(COUNTIF([1]CRITERIOS!$F$179:$F$199,$A6)>=1, IF(O6<>"", (O6/_xlfn.XLOOKUP(CONCATENATE(A6,L6),[1]MÁQUINAS!A:A,[1]MÁQUINAS!D:D))/24, (N6/_xlfn.XLOOKUP(CONCATENATE(A6,L6),[1]MÁQUINAS!A:A,[1]MÁQUINAS!D:D))/24), _xlfn.XLOOKUP($A6,'[1]DATOS PBI Artículos'!A:A,'[1]DATOS PBI Artículos'!AU:AU)) -> 3.78 | K6: =_xlfn.XLOOKUP($A6,'[1]DATOS PBI Artículos'!A:A,'[1]DATOS PBI Artículos'!AV:AV) -> 9.6170124 | L6: =_xlfn.XLOOKUP(A6,[1]MÁQUINAS!B:B,[1]MÁQUINAS!C:C) -> 509 | M6: {=_xlfn.XLOOKUP(A6,'[1]DATOS PBI Artículos'!A:A,'[1]DATOS PBI Artículos'!AX:$AX)} -> 589288.67 | N6: =IF(I6="DV", E6, IF(COUNTIF([1]CRITERIOS!$I$179:$I$199,$A6)>=1, _xlfn.XLOOKUP($A6,[1]CRITERIOS!$I$179:$I$199,[1]CRITERIOS!$J$179:$J$199), IF(COUNTIF([1]CRITERIOS!$L$179:$L$199,$A6)>=1, _xlfn.CEILING.MATH(IF($M6>$E6, $E6, IF($M6<$E6/ROUNDDOWN([1]CRITERIOS!$M$16/_xlfn.XLOOKUP($C6,[1]CRITERIOS!$K$25:$K$42,[1]CRITERIOS!$M$25:$M$42), 1), E6/ROUNDDOWN([1]CRITERIOS!$M$16/_xlfn.XLOOKUP($C6,[1]CRITERIOS!$K$25:$K$42,[1]CRITERIOS!$M$25:$M$42), 1), $M6)), _xlfn.XLOOKUP($A6,[1]CRITERIOS!$L$179:$L$200,[1]CRITERIOS!$M$179:$M$200)), _xlfn.CEILING.MATH(IF($M6>$E6, $E6, IF($M6<$E6/ROUNDDOWN([1]CRITERIOS!$M$16/_xlfn.XLOOKUP($C6,[1]CRITERIOS!$K$25:$K$42,[1]CRITERIOS!$M$25:$M$42), 1), E6/ROUNDDOWN([1]CRITERIOS!$M$16/_xlfn.XLOOKUP($C6,[1]CRITERIOS!$K$25:$K$42,[1]CRITERIOS!$M$25:$M$42), 1), $M6)),_xlfn.XLOOKUP(A6,'[1]DATOS PBI Artículos'!A:A,'[1]DATOS PBI Artículos'!Z:Z ))))) -> 725760 | Q6: =IF(AND(O6="",N6=0), 0, IF(COUNTIF([1]CRITERIOS!$F$179:$F$199,$A6)>=1, 1, IF(R6="MTO", $D6, ROUNDUP( IF(($E6-SUMIF('[1]DATOS PBI Artículos'!A:A,A6,'[1]DATOS PBI Artículos'!X:X)+($V6-_xlfn.XLOOKUP(A6,'[1]DATOS PBI Artículos'!A:A,'[1]DATOS PBI Artículos'!W:W)))<0, 0, IF(($E6-SUMIF('[1]DATOS PBI Artículos'!A:A,A6,'[1]DATOS PBI Artículos'!X:X)+$V6-_xlfn.XLOOKUP($A6,'[1]DATOS PBI Artículos'!A:A,'[1]DATOS PBI Artículos'!W:W))/IF($O6="",$N6,$O6)>ROUNDUP([1]CRITERIOS!$M$16/(IF(COUNTIF([1]CRITERIOS!$BG$11:$BG$201,L6)>=1,_xlfn.XLOOKUP($C6,[1]CRITERIOS!$K$25:$K$42,[1]CRITERIOS!$M$25:$M$42),_xlfn.XLOOKUP($C6,[1]CRITERIOS!$K$25:$K$42,[1]CRITERIOS!$M$25:$M$42))),0), ROUNDUP([1]CRITERIOS!$M$16/(IF(COUNTIF([1]CRITERIOS!$BG$11:$BG$201,$L6)>=1,_xlfn.XLOOKUP($C6,[1]CRITERIOS!$K$25:$K$42,[1]CRITERIOS!$M$25:$M$42),_xlfn.XLOOKUP($C6,[1]CRITERIOS!$K$25:$K$42,[1]CRITERIOS!$M$25:$M$42))),0), (E6+V6-SUMIF('[1]DATOS PBI Artículos'!A:A,A6,'[1]DATOS PBI Artículos'!X:X)-_xlfn.XLOOKUP(A6,'[1]DATOS PBI Artículos'!A:A,'[1]DATOS PBI Artículos'!W:W))/IF($O6="",$N6,$O6))),0)))) -> 1 | R6: =IF(U6<>"",U6,IF(F6="DV","MTO",IF(N6=0,"MTO",_xlfn.XLOOKUP(CONCATENATE(S6,T6),[1]CRITERIOS!$K$160:$K$168,[1]CRITERIOS!$N$160:$N$168)))) -> MTS | S6: =IF(G6="DV","MTO",IF(N6=0,"MTO",IF(OR(AND(N6=0,O6=""),IF(O6="",G6/N6,G6/O6)>[1]CRITERIOS!$G$163),"MTO",IF(IF(O6="",G6/N6,G6/O6)<[1]CRITERIOS!$H$161,"MTS","MTOS")))) -> MTS | T6: =IF(F6="DV","MTO",IF(OR(AND($N6=0,O6=""),$F6/$J6>[1]CRITERIOS!$G$170,$F6="DV"),"MTO",IF($F6/$J6<[1]CRITERIOS!$H$168,"MTS","MTOS"))) -> MTO | V6: =IF(R6="MTO","", IF($H6=0,(((($J6/$F6)*$G6)+$Z6)/$G6)*$G6, (($J6/$F6)*$G6)+$Z6)) -> 776960.62 | X6: =IF(R6="MTO",0,V6+N6) -> 1502720.6 | Y6: =IF(R6="MTO",0,Z6+(N6/2)) -> 995898.22 | Z6: =IF($R6="MTO", 0, ($H6+$K6*($E6/[1]CRITERIOS!$M$16))/[1]CRITERIOS!$X$48) -> 633018.22 | AA6: =ROUNDUP(($Y6/_xlfn.XLOOKUP($A6,'[1]DATOS PBI Artículos'!$A$4:$A$4,'[1]DATOS PBI Artículos'!$Z$4:$Z$4))/_xlfn.XLOOKUP(_xlfn.XLOOKUP($A6,'[1]DATOS PBI Artículos'!$A$4:$A$4,'[1]DATOS PBI Artículos'!$Y$4:$Y$4),[1]CRITERIOS!$P$79:$P$123,[1]CRITERIOS!$S$79:$S$123,),0) -> #N/A | AB6: {=IF((E6+V6-_xlfn.XLOOKUP(A6,'[1]DATOS PBI Artículos'!$A$4:$A$4,'[1]DATOS PBI Artículos'!$W$4:$W$4))/N6>ROUNDUP([1]CRITERIOS!$M$16/(IF(COUNTIF([1]CRITERIOS!$BG$11:$BG$201,L6)>=1,_xlfn.XLOOKUP(ARTÍCULOS!L6,[1]CRITERIOS!$BG$11:$BG$201,[1]CRITERIOS!$BJ$11:$BJ$201),_xlfn.XLOOKUP(ARTÍCULOS!C6,[1]CRITERIOS!$K$25:$K$42,[1]CRITERIOS!$M$25:$M$42))),0),ROUNDUP([1]CRITERIOS!$M$16/(IF(COUNTIF([1]CRITERIOS!$BG$11:$BG$201,L6)>=1,_xlfn.XLOOKUP(ARTÍCULOS!L6,[1]CRITERIOS!$BG$11:$BG$201:#REF!,[1]CRITERIOS!$BJ$11:$BJ$201),_xlfn.XLOOKUP(ARTÍCULOS!C6,[1]CRITERIOS!$K$25:$K$42,[1]CRITERIOS!$M$25:$M$42))),0),(E6+V6-_xlfn.XLOOKUP(A6,'[1]DATOS PBI Artículos'!$A$4:$A$4,'[1]DATOS PBI Artículos'!$W$4:$W$4))/N6)} -> #N/A | AC6: =IF(N6=0,"",(ROUNDUP((N6/2)/(_xlfn.XLOOKUP(A6,'[1]DATOS PBI Artículos'!$A$4:$A$4,'[1]DATOS PBI Artículos'!$Z$4:$Z$4)*_xlfn.XLOOKUP(_xlfn.XLOOKUP(A6,'[1]DATOS PBI Artículos'!$A$4:$A$4,'[1]DATOS PBI Artículos'!$Y$4:$Y$4),[1]CRITERIOS!$P$79:$P$123,[1]CRITERIOS!$S$79:$S$123)),0)*[1]CRITERIOS!$M$80*([1]CRITERIOS!$M$110/[1]CRITERIOS!$M$86)+(_xlfn.XLOOKUP(A6,'[1]DATOS PBI Artículos'!$A$4:$A$4,'[1]DATOS PBI Artículos'!$AA$4:$AA$4)*([1]CRITERIOS!$M$95+[1]CRITERIOS!$M$98)))/N6) -> #N/A | AD6: =IF(N6=0,"",(ROUNDUP((N6/2)/(_xlfn.XLOOKUP(A6,'[1]DATOS PBI Artículos'!$A$4:$A$4,'[1]DATOS PBI Artículos'!$Z$4:$Z$4)*_xlfn.XLOOKUP(_xlfn.XLOOKUP(A6,'[1]DATOS PBI Artículos'!$A$4:$A$4,'[1]DATOS PBI Artículos'!$Y$4:$Y$4),[1]CRITERIOS!$P$79:$P$123,[1]CRITERIOS!$S$79:$S$123)),0)*[1]CRITERIOS!$M$80*([1]CRITERIOS!$M$89*[1]CRITERIOS!$M$92)+((_xlfn.XLOOKUP(A6,'[1]DATOS PBI Artículos'!$A$4:$A$4,'[1]DATOS PBI Artículos'!$AA$4:$AA$4)/2)*([1]CRITERIOS!$M$95+[1]CRITERIOS!$M$98)))/N6) -> #N/A | AE6: =IF($R6="MTO","", IF($H6=0,ROUNDUP(((_xlfn.XLOOKUP($A6,'[1]DATOS PBI Artículos'!$A:$A,'[1]DATOS PBI Artículos'!$AL:$AL))/(_xlfn.XLOOKUP($AF$1,[1]CRITERIOS!$S$16:$S$39,[1]CRITERIOS!$Y$16:$Y$39))*$J6+$Z6)/$G6,0)*$G6, ((_xlfn.XLOOKUP($A6,'[1]DATOS PBI Artículos'!$A:$A,'[1]DATOS PBI Artículos'!$AL:$AL))/(_xlfn.XLOOKUP($AF$1,[1]CRITERIOS!$S$16:$S$39,[1]CRITERIOS!$Y$16:$Y$39))*$J6+$Z6))) -> 789312.78 | AG6: =IF($R6="MTO","", IF($H6=0,ROUNDUP(((_xlfn.XLOOKUP($A6,'[1]DATOS PBI Artículos'!$A:$A,'[1]DATOS PBI Artículos'!$AM:$AM))/(_xlfn.XLOOKUP($AH$1,[1]CRITERIOS!$S$16:$S$39,[1]CRITERIOS!$Y$16:$Y$39))*$J6+$Z6)/$G6,0)*$G6, ((_xlfn.XLOOKUP($A6,'[1]DATOS PBI Artículos'!$A:$A,'[1]DATOS PBI Artículos'!$AM:$AM))/(_xlfn.XLOOKUP($AH$1,[1]CRITERIOS!$S$16:$S$39,[1]CRITERIOS!$Y$16:$Y$39))*$J6+$Z6))) -> 745287.65 | AI6: =IF($R6="MTO","", IF($H6=0,ROUNDUP(((_xlfn.XLOOKUP($A6,'[1]DATOS PBI Artículos'!$A:$A,'[1]DATOS PBI Artículos'!$AN:$AN))/(_xlfn.XLOOKUP($AJ$1,[1]CRITERIOS!$S$16:$S$39,[1]CRITERIOS!$Y$16:$Y$39))*$J6+$Z6)/$G6,0)*$G6, ((_xlfn.XLOOKUP($A6,'[1]DATOS PBI Artículos'!$A:$A,'[1]DATOS PBI Artículos'!$AN:$AN))/(_xlfn.XLOOKUP($AJ$1,[1]CRITERIOS!$S$16:$S$39,[1]CRITERIOS!$Y$16:$Y$39))*$J6+$Z6))) -> 767488.84 | AK6: =IF($R6="MTO","", IF($H6=0,ROUNDUP(((_xlfn.XLOOKUP($A6,'[1]DATOS PBI Artículos'!$A:$A,'[1]DATOS PBI Artículos'!$AO:$AO))/(_xlfn.XLOOKUP($AL$1,[1]CRITERIOS!$S$16:$S$39,[1]CRITERIOS!$Y$16:$Y$39))*$J6+$Z6)/$G6,0)*$G6, ((_xlfn.XLOOKUP($A6,'[1]DATOS PBI Artículos'!$A:$A,'[1]DATOS PBI Artículos'!$AO:$AO))/(_xlfn.XLOOKUP($AL$1,[1]CRITERIOS!$S$16:$S$39,[1]CRITERIOS!$Y$16:$Y$39))*$J6+$Z6))) -> 779470.14
A7: 421809B | B7: =_xlfn.XLOOKUP($A7,'[1]DATOS PBI Artículos'!A:A,'[1]DATOS PBI Artículos'!B:B) -> 0 | C7: =_xlfn.XLOOKUP($A7,'[1]DATOS PBI Artículos'!A:A,'[1]DATOS PBI Artículos'!C:C) -> UA01 | D7: =_xlfn.XLOOKUP(A7,'[1]DATOS PBI Artículos'!A:A,'[1]DATOS PBI Artículos'!T:T) -> 7 | E7: =IF(_xlfn.XLOOKUP($A7,'[1]DATOS PBI Artículos'!A:A,'[1]DATOS PBI Artículos'!AK:AK)="",_xlfn.XLOOKUP($A7,'[1]DATOS PBI Artículos'!A:A,'[1]DATOS PBI Artículos'!AJ:AJ),_xlfn.XLOOKUP($A7,'[1]DATOS PBI Artículos'!A:A,'[1]DATOS PBI Artículos'!AK:AK)) -> 1900000 | F7: =_xlfn.XLOOKUP($A7,'[1]DATOS PBI Artículos'!A:A,'[1]DATOS PBI Artículos'!AP:AP) -> 10.333333 | G7: =_xlfn.XLOOKUP($A7,'[1]DATOS PBI Artículos'!A:A,'[1]DATOS PBI Artículos'!AR:AR) -> 300000 | H7: =_xlfn.XLOOKUP($A7,'[1]DATOS PBI Artículos'!A:A,'[1]DATOS PBI Artículos'!AT:AT) -> 95118.973 | I7: =_xlfn.XLOOKUP($A7,'[1]DATOS PBI Artículos'!A:A,'[1]DATOS PBI Artículos'!AS:AS) -> 100000 | J7: =IF(COUNTIF([1]CRITERIOS!$F$179:$F$199,$A7)>=1, IF(O7<>"", (O7/_xlfn.XLOOKUP(CONCATENATE(A7,L7),[1]MÁQUINAS!A:A,[1]MÁQUINAS!D:D))/24, (N7/_xlfn.XLOOKUP(CONCATENATE(A7,L7),[1]MÁQUINAS!A:A,[1]MÁQUINAS!D:D))/24), _xlfn.XLOOKUP($A7,'[1]DATOS PBI Artículos'!A:A,'[1]DATOS PBI Artículos'!AU:AU)) -> 23.742857 | K7: =_xlfn.XLOOKUP($A7,'[1]DATOS PBI Artículos'!A:A,'[1]DATOS PBI Artículos'!AV:AV) -> 3.9358298 | L7: =_xlfn.XLOOKUP(A7,[1]MÁQUINAS!B:B,[1]MÁQUINAS!C:C) -> 502 | M7: {=_xlfn.XLOOKUP(A7,'[1]DATOS PBI Artículos'!A:A,'[1]DATOS PBI Artículos'!AX:$AX)} -> 566636.94 | N7: =IF(I7="DV", E7, IF(COUNTIF([1]CRITERIOS!$I$179:$I$199,$A7)>=1, _xlfn.XLOOKUP($A7,[1]CRITERIOS!$I$179:$I$199,[1]CRITERIOS!$J$179:$J$199), IF(COUNTIF([1]CRITERIOS!$L$179:$L$199,$A7)>=1, _xlfn.CEILING.MATH(IF($M7>$E7, $E7, IF($M7<$E7/ROUNDDOWN([1]CRITERIOS!$M$16/_xlfn.XLOOKUP($C7,[1]CRITERIOS!$K$25:$K$42,[1]CRITERIOS!$M$25:$M$42), 1), E7/ROUNDDOWN([1]CRITERIOS!$M$16/_xlfn.XLOOKUP($C7,[1]CRITERIOS!$K$25:$K$42,[1]CRITERIOS!$M$25:$M$42), 1), $M7)), _xlfn.XLOOKUP($A7,[1]CRITERIOS!$L$179:$L$200,[1]CRITERIOS!$M$179:$M$200)), _xlfn.CEILING.MATH(IF($M7>$E7, $E7, IF($M7<$E7/ROUNDDOWN([1]CRITERIOS!$M$16/_xlfn.XLOOKUP($C7,[1]CRITERIOS!$K$25:$K$42,[1]CRITERIOS!$M$25:$M$42), 1), E7/ROUNDDOWN([1]CRITERIOS!$M$16/_xlfn.XLOOKUP($C7,[1]CRITERIOS!$K$25:$K$42,[1]CRITERIOS!$M$25:$M$42), 1), $M7)),_xlfn.XLOOKUP(A7,'[1]DATOS PBI Artículos'!A:A,'[1]DATOS PBI Artículos'!Z:Z ))))) -> 570000 | Q7: =IF(AND(O7="",N7=0), 0, IF(COUNTIF([1]CRITERIOS!$F$179:$F$199,$A7)>=1, 1, IF(R7="MTO", $D7, ROUNDUP( IF(($E7-SUMIF('[1]DATOS PBI Artículos'!A:A,A7,'[1]DATOS PBI Artículos'!X:X)+($V7-_xlfn.XLOOKUP(A7,'[1]DATOS PBI Artículos'!A:A,'[1]DATOS PBI Artículos'!W:W)))<0, 0, IF(($E7-SUMIF('[1]DATOS PBI Artículos'!A:A,A7,'[1]DATOS PBI Artículos'!X:X)+$V7-_xlfn.XLOOKUP($A7,'[1]DATOS PBI Artículos'!A:A,'[1]DATOS PBI Artículos'!W:W))/IF($O7="",$N7,$O7)>ROUNDUP([1]CRITERIOS!$M$16/(IF(COUNTIF([1]CRITERIOS!$BG$11:$BG$201,L7)>=1,_xlfn.XLOOKUP($C7,[1]CRITERIOS!$K$25:$K$42,[1]CRITERIOS!$M$25:$M$42),_xlfn.XLOOKUP($C7,[1]CRITERIOS!$K$25:$K$42,[1]CRITERIOS!$M$25:$M$42))),0), ROUNDUP([1]CRITERIOS!$M$16/(IF(COUNTIF([1]CRITERIOS!$BG$11:$BG$201,$L7)>=1,_xlfn.XLOOKUP($C7,[1]CRITERIOS!$K$25:$K$42,[1]CRITERIOS!$M$25:$M$42),_xlfn.XLOOKUP($C7,[1]CRITERIOS!$K$25:$K$42,[1]CRITERIOS!$M$25:$M$42))),0), (E7+V7-SUMIF('[1]DATOS PBI Artículos'!A:A,A7,'[1]DATOS PBI Artículos'!X:X)-_xlfn.XLOOKUP(A7,'[1]DATOS PBI Artículos'!A:A,'[1]DATOS PBI Artículos'!W:W))/IF($O7="",$N7,$O7))),0)))) -> 4 | R7: =IF(U7<>"",U7,IF(F7="DV","MTO",IF(N7=0,"MTO",_xlfn.XLOOKUP(CONCATENATE(S7,T7),[1]CRITERIOS!$K$160:$K$168,[1]CRITERIOS!$N$160:$N$168)))) -> MTS | S7: =IF(G7="DV","MTO",IF(N7=0,"MTO",IF(OR(AND(N7=0,O7=""),IF(O7="",G7/N7,G7/O7)>[1]CRITERIOS!$G$163),"MTO",IF(IF(O7="",G7/N7,G7/O7)<[1]CRITERIOS!$H$161,"MTS","MTOS")))) -> MTOS | T7: =IF(F7="DV","MTO",IF(OR(AND($N7=0,O7=""),$F7/$J7>[1]CRITERIOS!$G$170,$F7="DV"),"MTO",IF($F7/$J7<[1]CRITERIOS!$H$168,"MTS","MTOS"))) -> MTS | V7: =IF(R7="MTO","", IF($H7=0,(((($J7/$F7)*$G7)+$Z7)/$G7)*$G7, (($J7/$F7)*$G7)+$Z7)) -> 851664.31 | X7: =IF(R7="MTO",0,V7+N7) -> 1421664.3 | Y7: =IF(R7="MTO",0,Z7+(N7/2)) -> 447355.55 | Z7: =IF($R7="MTO", 0, ($H7+$K7*($E7/[1]CRITERIOS!$M$16))/[1]CRITERIOS!$X$48) -> 162355.55 | AA7: =ROUNDUP(($Y7/_xlfn.XLOOKUP($A7,'[1]DATOS PBI Artículos'!$A$4:$A$4,'[1]DATOS PBI Artículos'!$Z$4:$Z$4))/_xlfn.XLOOKUP(_xlfn.XLOOKUP($A7,'[1]DATOS PBI Artículos'!$A$4:$A$4,'[1]DATOS PBI Artículos'!$Y$4:$Y$4),[1]CRITERIOS!$P$79:$P$123,[1]CRITERIOS!$S$79:$S$123,),0) -> #N/A | AB7: {=IF((E7+V7-_xlfn.XLOOKUP(A7,'[1]DATOS PBI Artículos'!$A$4:$A$4,'[1]DATOS PBI Artículos'!$W$4:$W$4))/N7>ROUNDUP([1]CRITERIOS!$M$16/(IF(COUNTIF([1]CRITERIOS!$BG$11:$BG$201,L7)>=1,_xlfn.XLOOKUP(ARTÍCULOS!L7,[1]CRITERIOS!$BG$11:$BG$201,[1]CRITERIOS!$BJ$11:$BJ$201),_xlfn.XLOOKUP(ARTÍCULOS!C7,[1]CRITERIOS!$K$25:$K$42,[1]CRITERIOS!$M$25:$M$42))),0),ROUNDUP([1]CRITERIOS!$M$16/(IF(COUNTIF([1]CRITERIOS!$BG$11:$BG$201,L7)>=1,_xlfn.XLOOKUP(ARTÍCULOS!L7,[1]CRITERIOS!$BG$11:$BG$201:#REF!,[1]CRITERIOS!$BJ$11:$BJ$201),_xlfn.XLOOKUP(ARTÍCULOS!C7,[1]CRITERIOS!$K$25:$K$42,[1]CRITERIOS!$M$25:$M$42))),0),(E7+V7-_xlfn.XLOOKUP(A7,'[1]DATOS PBI Artículos'!$A$4:$A$4,'[1]DATOS PBI Artículos'!$W$4:$W$4))/N7)} -> #N/A | AC7: =IF(N7=0,"",(ROUNDUP((N7/2)/(_xlfn.XLOOKUP(A7,'[1]DATOS PBI Artículos'!$A$4:$A$4,'[1]DATOS PBI Artículos'!$Z$4:$Z$4)*_xlfn.XLOOKUP(_xlfn.XLOOKUP(A7,'[1]DATOS PBI Artículos'!$A$4:$A$4,'[1]DATOS PBI Artículos'!$Y$4:$Y$4),[1]CRITERIOS!$P$79:$P$123,[1]CRITERIOS!$S$79:$S$123)),0)*[1]CRITERIOS!$M$80*([1]CRITERIOS!$M$110/[1]CRITERIOS!$M$86)+(_xlfn.XLOOKUP(A7,'[1]DATOS PBI Artículos'!$A$4:$A$4,'[1]DATOS PBI Artículos'!$AA$4:$AA$4)*([1]CRITERIOS!$M$95+[1]CRITERIOS!$M$98)))/N7) -> #N/A | AD7: =IF(N7=0,"",(ROUNDUP((N7/2)/(_xlfn.XLOOKUP(A7,'[1]DATOS PBI Artículos'!$A$4:$A$4,'[1]DATOS PBI Artículos'!$Z$4:$Z$4)*_xlfn.XLOOKUP(_xlfn.XLOOKUP(A7,'[1]DATOS PBI Artículos'!$A$4:$A$4,'[1]DATOS PBI Artículos'!$Y$4:$Y$4),[1]CRITERIOS!$P$79:$P$123,[1]CRITERIOS!$S$79:$S$123)),0)*[1]CRITERIOS!$M$80*([1]CRITERIOS!$M$89*[1]CRITERIOS!$M$92)+((_xlfn.XLOOKUP(A7,'[1]DATOS PBI Artículos'!$A$4:$A$4,'[1]DATOS PBI Artículos'!$AA$4:$AA$4)/2)*([1]CRITERIOS!$M$95+[1]CRITERIOS!$M$98)))/N7) -> #N/A | AE7: =IF($R7="MTO","", IF($H7=0,ROUNDUP(((_xlfn.XLOOKUP($A7,'[1]DATOS PBI Artículos'!$A:$A,'[1]DATOS PBI Artículos'!$AL:$AL))/(_xlfn.XLOOKUP($AF$1,[1]CRITERIOS!$S$16:$S$39,[1]CRITERIOS!$Y$16:$Y$39))*$J7+$Z7)/$G7,0)*$G7, ((_xlfn.XLOOKUP($A7,'[1]DATOS PBI Artículos'!$A:$A,'[1]DATOS PBI Artículos'!$AL:$AL))/(_xlfn.XLOOKUP($AF$1,[1]CRITERIOS!$S$16:$S$39,[1]CRITERIOS!$Y$16:$Y$39))*$J7+$Z7))) -> 858014.68 | AG7: =IF($R7="MTO","", IF($H7=0,ROUNDUP(((_xlfn.XLOOKUP($A7,'[1]DATOS PBI Artículos'!$A:$A,'[1]DATOS PBI Artículos'!$AM:$AM))/(_xlfn.XLOOKUP($AH$1,[1]CRITERIOS!$S$16:$S$39,[1]CRITERIOS!$Y$16:$Y$39))*$J7+$Z7)/$G7,0)*$G7, ((_xlfn.XLOOKUP($A7,'[1]DATOS PBI Artículos'!$A:$A,'[1]DATOS PBI Artículos'!$AM:$AM))/(_xlfn.XLOOKUP($AH$1,[1]CRITERIOS!$S$16:$S$39,[1]CRITERIOS!$Y$16:$Y$39))*$J7+$Z7))) -> 662061.06 | AI7: =IF($R7="MTO","", IF($H7=0,ROUNDUP(((_xlfn.XLOOKUP($A7,'[1]DATOS PBI Artículos'!$A:$A,'[1]DATOS PBI Artículos'!$AN:$AN))/(_xlfn.XLOOKUP($AJ$1,[1]CRITERIOS!$S$16:$S$39,[1]CRITERIOS!$Y$16:$Y$39))*$J7+$Z7)/$G7,0)*$G7, ((_xlfn.XLOOKUP($A7,'[1]DATOS PBI Artículos'!$A:$A,'[1]DATOS PBI Artículos'!$AN:$AN))/(_xlfn.XLOOKUP($AJ$1,[1]CRITERIOS!$S$16:$S$39,[1]CRITERIOS!$Y$16:$Y$39))*$J7+$Z7))) -> 760877.41 | AK7: =IF($R7="MTO","", IF($H7=0,ROUNDUP(((_xlfn.XLOOKUP($A7,'[1]DATOS PBI Artículos'!$A:$A,'[1]DATOS PBI Artículos'!$AO:$AO))/(_xlfn.XLOOKUP($AL$1,[1]CRITERIOS!$S$16:$S$39,[1]CRITERIOS!$Y$16:$Y$39))*$J7+$Z7)/$G7,0)*$G7, ((_xlfn.XLOOKUP($A7,'[1]DATOS PBI Artículos'!$A:$A,'[1]DATOS PBI Artículos'!$AO:$AO))/(_xlfn.XLOOKUP($AL$1,[1]CRITERIOS!$S$16:$S$39,[1]CRITERIOS!$Y$16:$Y$39))*$J7+$Z7))) -> 814205.58
A8: 422016 | B8: =_xlfn.XLOOKUP($A8,'[1]DATOS PBI Artículos'!A:A,'[1]DATOS PBI Artículos'!B:B) -> 0 | C8: =_xlfn.XLOOKUP($A8,'[1]DATOS PBI Artículos'!A:A,'[1]DATOS PBI Artículos'!C:C) -> UA01 | D8: =_xlfn.XLOOKUP(A8,'[1]DATOS PBI Artículos'!A:A,'[1]DATOS PBI Artículos'!T:T) -> 19 | E8: =IF(_xlfn.XLOOKUP($A8,'[1]DATOS PBI Artículos'!A:A,'[1]DATOS PBI Artículos'!AK:AK)="",_xlfn.XLOOKUP($A8,'[1]DATOS PBI Artículos'!A:A,'[1]DATOS PBI Artículos'!AJ:AJ),_xlfn.XLOOKUP($A8,'[1]DATOS PBI Artículos'!A:A,'[1]DATOS PBI Artículos'!AK:AK)) -> 1300000 | F8: =_xlfn.XLOOKUP($A8,'[1]DATOS PBI Artículos'!A:A,'[1]DATOS PBI Artículos'!AP:AP) -> 4.125 | G8: =_xlfn.XLOOKUP($A8,'[1]DATOS PBI Artículos'!A:A,'[1]DATOS PBI Artículos'!AR:AR) -> 80000 | H8: =_xlfn.XLOOKUP($A8,'[1]DATOS PBI Artículos'!A:A,'[1]DATOS PBI Artículos'!AT:AT) -> 7859.0525 | I8: =_xlfn.XLOOKUP($A8,'[1]DATOS PBI Artículos'!A:A,'[1]DATOS PBI Artículos'!AS:AS) -> 20000 | J8: =IF(COUNTIF([1]CRITERIOS!$F$179:$F$199,$A8)>=1, IF(O8<>"", (O8/_xlfn.XLOOKUP(CONCATENATE(A8,L8),[1]MÁQUINAS!A:A,[1]MÁQUINAS!D:D))/24, (N8/_xlfn.XLOOKUP(CONCATENATE(A8,L8),[1]MÁQUINAS!A:A,[1]MÁQUINAS!D:D))/24), _xlfn.XLOOKUP($A8,'[1]DATOS PBI Artículos'!A:A,'[1]DATOS PBI Artículos'!AU:AU)) -> 12.280992 | K8: =_xlfn.XLOOKUP($A8,'[1]DATOS PBI Artículos'!A:A,'[1]DATOS PBI Artículos'!AV:AV) -> 0.98508156 | L8: =_xlfn.XLOOKUP(A8,[1]MÁQUINAS!B:B,[1]MÁQUINAS!C:C) -> 522 | M8: {=_xlfn.XLOOKUP(A8,'[1]DATOS PBI Artículos'!A:A,'[1]DATOS PBI Artículos'!AX:$AX)} -> 358928.61 | N8: =IF(I8="DV", E8, IF(COUNTIF([1]CRITERIOS!$I$179:$I$199,$A8)>=1, _xlfn.XLOOKUP($A8,[1]CRITERIOS!$I$179:$I$199,[1]CRITERIOS!$J$179:$J$199), IF(COUNTIF([1]CRITERIOS!$L$179:$L$199,$A8)>=1, _xlfn.CEILING.MATH(IF($M8>$E8, $E8, IF($M8<$E8/ROUNDDOWN([1]CRITERIOS!$M$16/_xlfn.XLOOKUP($C8,[1]CRITERIOS!$K$25:$K$42,[1]CRITERIOS!$M$25:$M$42), 1), E8/ROUNDDOWN([1]CRITERIOS!$M$16/_xlfn.XLOOKUP($C8,[1]CRITERIOS!$K$25:$K$42,[1]CRITERIOS!$M$25:$M$42), 1), $M8)), _xlfn.XLOOKUP($A8,[1]CRITERIOS!$L$179:$L$200,[1]CRITERIOS!$M$179:$M$200)), _xlfn.CEILING.MATH(IF($M8>$E8, $E8, IF($M8<$E8/ROUNDDOWN([1]CRITERIOS!$M$16/_xlfn.XLOOKUP($C8,[1]CRITERIOS!$K$25:$K$42,[1]CRITERIOS!$M$25:$M$42), 1), E8/ROUNDDOWN([1]CRITERIOS!$M$16/_xlfn.XLOOKUP($C8,[1]CRITERIOS!$K$25:$K$42,[1]CRITERIOS!$M$25:$M$42), 1), $M8)),_xlfn.XLOOKUP(A8,'[1]DATOS PBI Artículos'!A:A,'[1]DATOS PBI Artículos'!Z:Z ))))) -> 360000 | Q8: =IF(AND(O8="",N8=0), 0, IF(COUNTIF([1]CRITERIOS!$F$179:$F$199,$A8)>=1, 1, IF(R8="MTO", $D8, ROUNDUP( IF(($E8-SUMIF('[1]DATOS PBI Artículos'!A:A,A8,'[1]DATOS PBI Artículos'!X:X)+($V8-_xlfn.XLOOKUP(A8,'[1]DATOS PBI Artículos'!A:A,'[1]DATOS PBI Artículos'!W:W)))<0, 0, IF(($E8-SUMIF('[1]DATOS PBI Artículos'!A:A,A8,'[1]DATOS PBI Artículos'!X:X)+$V8-_xlfn.XLOOKUP($A8,'[1]DATOS PBI Artículos'!A:A,'[1]DATOS PBI Artículos'!W:W))/IF($O8="",$N8,$O8)>ROUNDUP([1]CRITERIOS!$M$16/(IF(COUNTIF([1]CRITERIOS!$BG$11:$BG$201,L8)>=1,_xlfn.XLOOKUP($C8,[1]CRITERIOS!$K$25:$K$42,[1]CRITERIOS!$M$25:$M$42),_xlfn.XLOOKUP($C8,[1]CRITERIOS!$K$25:$K$42,[1]CRITERIOS!$M$25:$M$42))),0), ROUNDUP([1]CRITERIOS!$M$16/(IF(COUNTIF([1]CRITERIOS!$BG$11:$BG$201,$L8)>=1,_xlfn.XLOOKUP($C8,[1]CRITERIOS!$K$25:$K$42,[1]CRITERIOS!$M$25:$M$42),_xlfn.XLOOKUP($C8,[1]CRITERIOS!$K$25:$K$42,[1]CRITERIOS!$M$25:$M$42))),0), (E8+V8-SUMIF('[1]DATOS PBI Artículos'!A:A,A8,'[1]DATOS PBI Artículos'!X:X)-_xlfn.XLOOKUP(A8,'[1]DATOS PBI Artículos'!A:A,'[1]DATOS PBI Artículos'!W:W))/IF($O8="",$N8,$O8))),0)))) -> 4 | R8: =IF(U8<>"",U8,IF(F8="DV","MTO",IF(N8=0,"MTO",_xlfn.XLOOKUP(CONCATENATE(S8,T8),[1]CRITERIOS!$K$160:$K$168,[1]CRITERIOS!$N$160:$N$168)))) -> MTS | S8: =IF(G8="DV","MTO",IF(N8=0,"MTO",IF(OR(AND(N8=0,O8=""),IF(O8="",G8/N8,G8/O8)>[1]CRITERIOS!$G$163),"MTO",IF(IF(O8="",G8/N8,G8/O8)<[1]CRITERIOS!$H$161,"MTS","MTOS")))) -> MTS | T8: =IF(F8="DV","MTO",IF(OR(AND($N8=0,O8=""),$F8/$J8>[1]CRITERIOS!$G$170,$F8="DV"),"MTO",IF($F8/$J8<[1]CRITERIOS!$H$168,"MTS","MTOS"))) -> MTS | V8: =IF(R8="MTO","", IF($H8=0,(((($J8/$F8)*$G8)+$Z8)/$G8)*$G8, (($J8/$F8)*$G8)+$Z8)) -> 258954.98 | X8: =IF(R8="MTO",0,V8+N8) -> 618954.98 | Y8: =IF(R8="MTO",0,Z8+(N8/2)) -> 200778.17 | Z8: =IF($R8="MTO", 0, ($H8+$K8*($E8/[1]CRITERIOS!$M$16))/[1]CRITERIOS!$X$48) -> 20778.166 | AA8: =ROUNDUP(($Y8/_xlfn.XLOOKUP($A8,'[1]DATOS PBI Artículos'!$A$4:$A$4,'[1]DATOS PBI Artículos'!$Z$4:$Z$4))/_xlfn.XLOOKUP(_xlfn.XLOOKUP($A8,'[1]DATOS PBI Artículos'!$A$4:$A$4,'[1]DATOS PBI Artículos'!$Y$4:$Y$4),[1]CRITERIOS!$P$79:$P$123,[1]CRITERIOS!$S$79:$S$123,),0) -> #N/A | AB8: {=IF((E8+V8-_xlfn.XLOOKUP(A8,'[1]DATOS PBI Artículos'!$A$4:$A$4,'[1]DATOS PBI Artículos'!$W$4:$W$4))/N8>ROUNDUP([1]CRITERIOS!$M$16/(IF(COUNTIF([1]CRITERIOS!$BG$11:$BG$201,L8)>=1,_xlfn.XLOOKUP(ARTÍCULOS!L8,[1]CRITERIOS!$BG$11:$BG$201,[1]CRITERIOS!$BJ$11:$BJ$201),_xlfn.XLOOKUP(ARTÍCULOS!C8,[1]CRITERIOS!$K$25:$K$42,[1]CRITERIOS!$M$25:$M$42))),0),ROUNDUP([1]CRITERIOS!$M$16/(IF(COUNTIF([1]CRITERIOS!$BG$11:$BG$201,L8)>=1,_xlfn.XLOOKUP(ARTÍCULOS!L8,[1]CRITERIOS!$BG$11:$BG$201:#REF!,[1]CRITERIOS!$BJ$11:$BJ$201),_xlfn.XLOOKUP(ARTÍCULOS!C8,[1]CRITERIOS!$K$25:$K$42,[1]CRITERIOS!$M$25:$M$42))),0),(E8+V8-_xlfn.XLOOKUP(A8,'[1]DATOS PBI Artículos'!$A$4:$A$4,'[1]DATOS PBI Artículos'!$W$4:$W$4))/N8)} -> #N/A | AC8: =IF(N8=0,"",(ROUNDUP((N8/2)/(_xlfn.XLOOKUP(A8,'[1]DATOS PBI Artículos'!$A$4:$A$4,'[1]DATOS PBI Artículos'!$Z$4:$Z$4)*_xlfn.XLOOKUP(_xlfn.XLOOKUP(A8,'[1]DATOS PBI Artículos'!$A$4:$A$4,'[1]DATOS PBI Artículos'!$Y$4:$Y$4),[1]CRITERIOS!$P$79:$P$123,[1]CRITERIOS!$S$79:$S$123)),0)*[1]CRITERIOS!$M$80*([1]CRITERIOS!$M$110/[1]CRITERIOS!$M$86)+(_xlfn.XLOOKUP(A8,'[1]DATOS PBI Artículos'!$A$4:$A$4,'[1]DATOS PBI Artículos'!$AA$4:$AA$4)*([1]CRITERIOS!$M$95+[1]CRITERIOS!$M$98)))/N8) -> #N/A | AD8: =IF(N8=0,"",(ROUNDUP((N8/2)/(_xlfn.XLOOKUP(A8,'[1]DATOS PBI Artículos'!$A$4:$A$4,'[1]DATOS PBI Artículos'!$Z$4:$Z$4)*_xlfn.XLOOKUP(_xlfn.XLOOKUP(A8,'[1]DATOS PBI Artículos'!$A$4:$A$4,'[1]DATOS PBI Artículos'!$Y$4:$Y$4),[1]CRITERIOS!$P$79:$P$123,[1]CRITERIOS!$S$79:$S$123)),0)*[1]CRITERIOS!$M$80*([1]CRITERIOS!$M$89*[1]CRITERIOS!$M$92)+((_xlfn.XLOOKUP(A8,'[1]DATOS PBI Artículos'!$A$4:$A$4,'[1]DATOS PBI Artículos'!$AA$4:$AA$4)/2)*([1]CRITERIOS!$M$95+[1]CRITERIOS!$M$98)))/N8) -> #N/A | AE8: =IF($R8="MTO","", IF($H8=0,ROUNDUP(((_xlfn.XLOOKUP($A8,'[1]DATOS PBI Artículos'!$A:$A,'[1]DATOS PBI Artículos'!$AL:$AL))/(_xlfn.XLOOKUP($AF$1,[1]CRITERIOS!$S$16:$S$39,[1]CRITERIOS!$Y$16:$Y$39))*$J8+$Z8)/$G8,0)*$G8, ((_xlfn.XLOOKUP($A8,'[1]DATOS PBI Artículos'!$A:$A,'[1]DATOS PBI Artículos'!$AL:$AL))/(_xlfn.XLOOKUP($AF$1,[1]CRITERIOS!$S$16:$S$39,[1]CRITERIOS!$Y$16:$Y$39))*$J8+$Z8))) -> 266977.4 | AG8: =IF($R8="MTO","", IF($H8=0,ROUNDUP(((_xlfn.XLOOKUP($A8,'[1]DATOS PBI Artículos'!$A:$A,'[1]DATOS PBI Artículos'!$AM:$AM))/(_xlfn.XLOOKUP($AH$1,[1]CRITERIOS!$S$16:$S$39,[1]CRITERIOS!$Y$16:$Y$39))*$J8+$Z8)/$G8,0)*$G8, ((_xlfn.XLOOKUP($A8,'[1]DATOS PBI Artículos'!$A:$A,'[1]DATOS PBI Artículos'!$AM:$AM))/(_xlfn.XLOOKUP($AH$1,[1]CRITERIOS!$S$16:$S$39,[1]CRITERIOS!$Y$16:$Y$39))*$J8+$Z8))) -> 197627.87 | AI8: =IF($R8="MTO","", IF($H8=0,ROUNDUP(((_xlfn.XLOOKUP($A8,'[1]DATOS PBI Artículos'!$A:$A,'[1]DATOS PBI Artículos'!$AN:$AN))/(_xlfn.XLOOKUP($AJ$1,[1]CRITERIOS!$S$16:$S$39,[1]CRITERIOS!$Y$16:$Y$39))*$J8+$Z8)/$G8,0)*$G8, ((_xlfn.XLOOKUP($A8,'[1]DATOS PBI Artículos'!$A:$A,'[1]DATOS PBI Artículos'!$AN:$AN))/(_xlfn.XLOOKUP($AJ$1,[1]CRITERIOS!$S$16:$S$39,[1]CRITERIOS!$Y$16:$Y$39))*$J8+$Z8))) -> 232599.76 | AK8: =IF($R8="MTO","", IF($H8=0,ROUNDUP(((_xlfn.XLOOKUP($A8,'[1]DATOS PBI Artículos'!$A:$A,'[1]DATOS PBI Artículos'!$AO:$AO))/(_xlfn.XLOOKUP($AL$1,[1]CRITERIOS!$S$16:$S$39,[1]CRITERIOS!$Y$16:$Y$39))*$J8+$Z8)/$G8,0)*$G8, ((_xlfn.XLOOKUP($A8,'[1]DATOS PBI Artículos'!$A:$A,'[1]DATOS PBI Artículos'!$AO:$AO))/(_xlfn.XLOOKUP($AL$1,[1]CRITERIOS!$S$16:$S$39,[1]CRITERIOS!$Y$16:$Y$39))*$J8+$Z8))) -> 251473.02
A9: 421109C | B9: =_xlfn.XLOOKUP($A9,'[1]DATOS PBI Artículos'!A:A,'[1]DATOS PBI Artículos'!B:B) -> 0 | C9: =_xlfn.XLOOKUP($A9,'[1]DATOS PBI Artículos'!A:A,'[1]DATOS PBI Artículos'!C:C) -> UA01 | D9: =_xlfn.XLOOKUP(A9,'[1]DATOS PBI Artículos'!A:A,'[1]DATOS PBI Artículos'!T:T) -> 5 | E9: =IF(_xlfn.XLOOKUP($A9,'[1]DATOS PBI Artículos'!A:A,'[1]DATOS PBI Artículos'!AK:AK)="",_xlfn.XLOOKUP($A9,'[1]DATOS PBI Artículos'!A:A,'[1]DATOS PBI Artículos'!AJ:AJ),_xlfn.XLOOKUP($A9,'[1]DATOS PBI Artículos'!A:A,'[1]DATOS PBI Artículos'!AK:AK)) -> 1200000 | F9: =_xlfn.XLOOKUP($A9,'[1]DATOS PBI Artículos'!A:A,'[1]DATOS PBI Artículos'!AP:AP) -> 20.666667 | G9: =_xlfn.XLOOKUP($A9,'[1]DATOS PBI Artículos'!A:A,'[1]DATOS PBI Artículos'!AR:AR) -> 300000 | H9: =_xlfn.XLOOKUP($A9,'[1]DATOS PBI Artículos'!A:A,'[1]DATOS PBI Artículos'!AT:AT) -> 0 | I9: =_xlfn.XLOOKUP($A9,'[1]DATOS PBI Artículos'!A:A,'[1]DATOS PBI Artículos'!AS:AS) -> 300000 | J9: =IF(COUNTIF([1]CRITERIOS!$F$179:$F$199,$A9)>=1, IF(O9<>"", (O9/_xlfn.XLOOKUP(CONCATENATE(A9,L9),[1]MÁQUINAS!A:A,[1]MÁQUINAS!D:D))/24, (N9/_xlfn.XLOOKUP(CONCATENATE(A9,L9),[1]MÁQUINAS!A:A,[1]MÁQUINAS!D:D))/24), _xlfn.XLOOKUP($A9,'[1]DATOS PBI Artículos'!A:A,'[1]DATOS PBI Artículos'!AU:AU)) -> 20.333333 | K9: =_xlfn.XLOOKUP($A9,'[1]DATOS PBI Artículos'!A:A,'[1]DATOS PBI Artículos'!AV:AV) -> 2.3094011 | L9: =_xlfn.XLOOKUP(A9,[1]MÁQUINAS!B:B,[1]MÁQUINAS!C:C) -> 507 | M9: {=_xlfn.XLOOKUP(A9,'[1]DATOS PBI Artículos'!A:A,'[1]DATOS PBI Artículos'!AX:$AX)} -> 159402.21 | N9: =IF(I9="DV", E9, IF(COUNTIF([1]CRITERIOS!$I$179:$I$199,$A9)>=1, _xlfn.XLOOKUP($A9,[1]CRITERIOS!$I$179:$I$199,[1]CRITERIOS!$J$179:$J$199), IF(COUNTIF([1]CRITERIOS!$L$179:$L$199,$A9)>=1, _xlfn.CEILING.MATH(IF($M9>$E9, $E9, IF($M9<$E9/ROUNDDOWN([1]CRITERIOS!$M$16/_xlfn.XLOOKUP($C9,[1]CRITERIOS!$K$25:$K$42,[1]CRITERIOS!$M$25:$M$42), 1), E9/ROUNDDOWN([1]CRITERIOS!$M$16/_xlfn.XLOOKUP($C9,[1]CRITERIOS!$K$25:$K$42,[1]CRITERIOS!$M$25:$M$42), 1), $M9)), _xlfn.XLOOKUP($A9,[1]CRITERIOS!$L$179:$L$200,[1]CRITERIOS!$M$179:$M$200)), _xlfn.CEILING.MATH(IF($M9>$E9, $E9, IF($M9<$E9/ROUNDDOWN([1]CRITERIOS!$M$16/_xlfn.XLOOKUP($C9,[1]CRITERIOS!$K$25:$K$42,[1]CRITERIOS!$M$25:$M$42), 1), E9/ROUNDDOWN([1]CRITERIOS!$M$16/_xlfn.XLOOKUP($C9,[1]CRITERIOS!$K$25:$K$42,[1]CRITERIOS!$M$25:$M$42), 1), $M9)),_xlfn.XLOOKUP(A9,'[1]DATOS PBI Artículos'!A:A,'[1]DATOS PBI Artículos'!Z:Z ))))) -> 325500 | Q9: =IF(AND(O9="",N9=0), 0, IF(COUNTIF([1]CRITERIOS!$F$179:$F$199,$A9)>=1, 1, IF(R9="MTO", $D9, ROUNDUP( IF(($E9-SUMIF('[1]DATOS PBI Artículos'!A:A,A9,'[1]DATOS PBI Artículos'!X:X)+($V9-_xlfn.XLOOKUP(A9,'[1]DATOS PBI Artículos'!A:A,'[1]DATOS PBI Artículos'!W:W)))<0, 0, IF(($E9-SUMIF('[1]DATOS PBI Artículos'!A:A,A9,'[1]DATOS PBI Artículos'!X:X)+$V9-_xlfn.XLOOKUP($A9,'[1]DATOS PBI Artículos'!A:A,'[1]DATOS PBI Artículos'!W:W))/IF($O9="",$N9,$O9)>ROUNDUP([1]CRITERIOS!$M$16/(IF(COUNTIF([1]CRITERIOS!$BG$11:$BG$201,L9)>=1,_xlfn.XLOOKUP($C9,[1]CRITERIOS!$K$25:$K$42,[1]CRITERIOS!$M$25:$M$42),_xlfn.XLOOKUP($C9,[1]CRITERIOS!$K$25:$K$42,[1]CRITERIOS!$M$25:$M$42))),0), ROUNDUP([1]CRITERIOS!$M$16/(IF(COUNTIF([1]CRITERIOS!$BG$11:$BG$201,$L9)>=1,_xlfn.XLOOKUP($C9,[1]CRITERIOS!$K$25:$K$42,[1]CRITERIOS!$M$25:$M$42),_xlfn.XLOOKUP($C9,[1]CRITERIOS!$K$25:$K$42,[1]CRITERIOS!$M$25:$M$42))),0), (E9+V9-SUMIF('[1]DATOS PBI Artículos'!A:A,A9,'[1]DATOS PBI Artículos'!X:X)-_xlfn.XLOOKUP(A9,'[1]DATOS PBI Artículos'!A:A,'[1]DATOS PBI Artículos'!W:W))/IF($O9="",$N9,$O9))),0)))) -> 4 | R9: =IF(U9<>"",U9,IF(F9="DV","MTO",IF(N9=0,"MTO",_xlfn.XLOOKUP(CONCATENATE(S9,T9),[1]CRITERIOS!$K$160:$K$168,[1]CRITERIOS!$N$160:$N$168)))) -> MTS | S9: =IF(G9="DV","MTO",IF(N9=0,"MTO",IF(OR(AND(N9=0,O9=""),IF(O9="",G9/N9,G9/O9)>[1]CRITERIOS!$G$163),"MTO",IF(IF(O9="",G9/N9,G9/O9)<[1]CRITERIOS!$H$161,"MTS","MTOS")))) -> MTO | T9: =IF(F9="DV","MTO",IF(OR(AND($N9=0,O9=""),$F9/$J9>[1]CRITERIOS!$G$170,$F9="DV"),"MTO",IF($F9/$J9<[1]CRITERIOS!$H$168,"MTS","MTOS"))) -> MTS | V9: =IF(R9="MTO","", IF($H9=0,(((($J9/$F9)*$G9)+$Z9)/$G9)*$G9, (($J9/$F9)*$G9)+$Z9)) -> 325953.3 | X9: =IF(R9="MTO",0,V9+N9) -> 651453.3 | Y9: =IF(R9="MTO",0,Z9+(N9/2)) -> 193542.01 | Z9: =IF($R9="MTO", 0, ($H9+$K9*($E9/[1]CRITERIOS!$M$16))/[1]CRITERIOS!$X$48) -> 30792.014 | AA9: =ROUNDUP(($Y9/_xlfn.XLOOKUP($A9,'[1]DATOS PBI Artículos'!$A$4:$A$4,'[1]DATOS PBI Artículos'!$Z$4:$Z$4))/_xlfn.XLOOKUP(_xlfn.XLOOKUP($A9,'[1]DATOS PBI Artículos'!$A$4:$A$4,'[1]DATOS PBI Artículos'!$Y$4:$Y$4),[1]CRITERIOS!$P$79:$P$123,[1]CRITERIOS!$S$79:$S$123,),0) -> #N/A | AB9: {=IF((E9+V9-_xlfn.XLOOKUP(A9,'[1]DATOS PBI Artículos'!$A$4:$A$4,'[1]DATOS PBI Artículos'!$W$4:$W$4))/N9>ROUNDUP([1]CRITERIOS!$M$16/(IF(COUNTIF([1]CRITERIOS!$BG$11:$BG$201,L9)>=1,_xlfn.XLOOKUP(ARTÍCULOS!L9,[1]CRITERIOS!$BG$11:$BG$201,[1]CRITERIOS!$BJ$11:$BJ$201),_xlfn.XLOOKUP(ARTÍCULOS!C9,[1]CRITERIOS!$K$25:$K$42,[1]CRITERIOS!$M$25:$M$42))),0),ROUNDUP([1]CRITERIOS!$M$16/(IF(COUNTIF([1]CRITERIOS!$BG$11:$BG$201,L9)>=1,_xlfn.XLOOKUP(ARTÍCULOS!L9,[1]CRITERIOS!$BG$11:$BG$201:#REF!,[1]CRITERIOS!$BJ$11:$BJ$201),_xlfn.XLOOKUP(ARTÍCULOS!C9,[1]CRITERIOS!$K$25:$K$42,[1]CRITERIOS!$M$25:$M$42))),0),(E9+V9-_xlfn.XLOOKUP(A9,'[1]DATOS PBI Artículos'!$A$4:$A$4,'[1]DATOS PBI Artículos'!$W$4:$W$4))/N9)} -> #N/A | AC9: =IF(N9=0,"",(ROUNDUP((N9/2)/(_xlfn.XLOOKUP(A9,'[1]DATOS PBI Artículos'!$A$4:$A$4,'[1]DATOS PBI Artículos'!$Z$4:$Z$4)*_xlfn.XLOOKUP(_xlfn.XLOOKUP(A9,'[1]DATOS PBI Artículos'!$A$4:$A$4,'[1]DATOS PBI Artículos'!$Y$4:$Y$4),[1]CRITERIOS!$P$79:$P$123,[1]CRITERIOS!$S$79:$S$123)),0)*[1]CRITERIOS!$M$80*([1]CRITERIOS!$M$110/[1]CRITERIOS!$M$86)+(_xlfn.XLOOKUP(A9,'[1]DATOS PBI Artículos'!$A$4:$A$4,'[1]DATOS PBI Artículos'!$AA$4:$AA$4)*([1]CRITERIOS!$M$95+[1]CRITERIOS!$M$98)))/N9) -> #N/A | AD9: =IF(N9=0,"",(ROUNDUP((N9/2)/(_xlfn.XLOOKUP(A9,'[1]DATOS PBI Artículos'!$A$4:$A$4,'[1]DATOS PBI Artículos'!$Z$4:$Z$4)*_xlfn.XLOOKUP(_xlfn.XLOOKUP(A9,'[1]DATOS PBI Artículos'!$A$4:$A$4,'[1]DATOS PBI Artículos'!$Y$4:$Y$4),[1]CRITERIOS!$P$79:$P$123,[1]CRITERIOS!$S$79:$S$123)),0)*[1]CRITERIOS!$M$80*([1]CRITERIOS!$M$89*[1]CRITERIOS!$M$92)+((_xlfn.XLOOKUP(A9,'[1]DATOS PBI Artículos'!$A$4:$A$4,'[1]DATOS PBI Artículos'!$AA$4:$AA$4)/2)*([1]CRITERIOS!$M$95+[1]CRITERIOS!$M$98)))/N9) -> #N/A | AE9: =IF($R9="MTO","", IF($H9=0,ROUNDUP(((_xlfn.XLOOKUP($A9,'[1]DATOS PBI Artículos'!$A:$A,'[1]DATOS PBI Artículos'!$AL:$AL))/(_xlfn.XLOOKUP($AF$1,[1]CRITERIOS!$S$16:$S$39,[1]CRITERIOS!$Y$16:$Y$39))*$J9+$Z9)/$G9,0)*$G9, ((_xlfn.XLOOKUP($A9,'[1]DATOS PBI Artículos'!$A:$A,'[1]DATOS PBI Artículos'!$AL:$AL))/(_xlfn.XLOOKUP($AF$1,[1]CRITERIOS!$S$16:$S$39,[1]CRITERIOS!$Y$16:$Y$39))*$J9+$Z9))) -> 600000 | AG9: =IF($R9="MTO","", IF($H9=0,ROUNDUP(((_xlfn.XLOOKUP($A9,'[1]DATOS PBI Artículos'!$A:$A,'[1]DATOS PBI Artículos'!$AM:$AM))/(_xlfn.XLOOKUP($AH$1,[1]CRITERIOS!$S$16:$S$39,[1]CRITERIOS!$Y$16:$Y$39))*$J9+$Z9)/$G9,0)*$G9, ((_xlfn.XLOOKUP($A9,'[1]DATOS PBI Artículos'!$A:$A,'[1]DATOS PBI Artículos'!$AM:$AM))/(_xlfn.XLOOKUP($AH$1,[1]CRITERIOS!$S$16:$S$39,[1]CRITERIOS!$Y$16:$Y$39))*$J9+$Z9))) -> 600000 | AI9: =IF($R9="MTO","", IF($H9=0,ROUNDUP(((_xlfn.XLOOKUP($A9,'[1]DATOS PBI Artículos'!$A:$A,'[1]DATOS PBI Artículos'!$AN:$AN))/(_xlfn.XLOOKUP($AJ$1,[1]CRITERIOS!$S$16:$S$39,[1]CRITERIOS!$Y$16:$Y$39))*$J9+$Z9)/$G9,0)*$G9, ((_xlfn.XLOOKUP($A9,'[1]DATOS PBI Artículos'!$A:$A,'[1]DATOS PBI Artículos'!$AN:$AN))/(_xlfn.XLOOKUP($AJ$1,[1]CRITERIOS!$S$16:$S$39,[1]CRITERIOS!$Y$16:$Y$39))*$J9+$Z9))) -> 600000 | AK9: =IF($R9="MTO","", IF($H9=0,ROUNDUP(((_xlfn.XLOOKUP($A9,'[1]DATOS PBI Artículos'!$A:$A,'[1]DATOS PBI Artículos'!$AO:$AO))/(_xlfn.XLOOKUP($AL$1,[1]CRITERIOS!$S$16:$S$39,[1]CRITERIOS!$Y$16:$Y$39))*$J9+$Z9)/$G9,0)*$G9, ((_xlfn.XLOOKUP($A9,'[1]DATOS PBI Artículos'!$A:$A,'[1]DATOS PBI Artículos'!$AO:$AO))/(_xlfn.XLOOKUP($AL$1,[1]CRITERIOS!$S$16:$S$39,[1]CRITERIOS!$Y$16:$Y$39))*$J9+$Z9))) -> 600000
